Workbook

Sheet Tính toán chi tiết động cơ  (2)
J2: Quãng đường di chuyển xấp xỉ 9m
B3: Thiết kế truyền động cơ cấu xe con cầu trục với thông số như sau:
A4: STT | B4: Thông số | C4: Kí hiệu | D4: Công thức tính | E4: Giá trị | F4: Đơn vị | I4: STT | J4: Thông số | K4: Kí hiệu | L4: Công thức tính | M4: Giá trị | N4: Đơn vị
A5: 1 | B5: Hàng đơn vị của STT trong ds lớp | C5: x | E5: 1 | H5: Có tải | I5: 1 | J5: Thời gian tăng tốc | K5: t1 | M5: 2 | N5: s
A6: 2 | B6: Tải trọng định mức | C6: M | E6: 11111 | F6: kg | I6: 2 | J6: Tăng đến giá trị vận tốc | K6: v1 | M6: 0.11 | N6: m/s
A7: 3 | B7: Khối lượng cơ cấu nâng hạ | C7: m | E7: 211 | F7: kg | I7: 3 | J7: Gia tốc khi tăng tốc | K7: a1 | L7: a1=v1/t1 | M7: 0.055 | N7: m/s^2
A8: 4 | B8: Chiều cao nâng | C8: h | E8: 11 | F8: m | I8: 4 | J8: Lực khi tăng tốc | K8: Ft1 | L8: Ft1=(M+m)*(mu*g+a1) | M8: 22836.5 | N8: N
A9: 5 | B9: Tốc độ tối đa | C9: v | E9: 0.11 | F9: m/s | I9: 5 | J9: Tốc độ trung bình khi tăng tốc | K9: vtb1 | L9: vtb1=s1/t1=1/2*a1*t1 | M9: 0.055 | N9: m/s
A10: 6 | B10: Gia tốc cực đại | C10: a | E10: 0.5 | F10: m/s^2 | I10: 6 | J10: Công suất trung bình khi tăng tốc | K10: P1 | L10: P1=Ft1*vtb1 | M10: 1256 | N10: W
A11: 7 | B11: Độ giật cực đại | C11: rô | E11: 2 | F11: m/s^3 | I11: 7 | J11: Thời gian cđ thẳng đều | K11: t2 | M11: 80 | N11: s
A12: 8 | B12: Đường kính bánh xe | C12: d | E12: 0.25 | F12: m | I12: 8 | J12: Lực khi cđ đều | K12: F2 | L12: F2=(M+m)*mu*g | M12: 22213.76 | N12: N
A13: 9 | B13: Tỷ số truyền | C13: i | E13: 100 | I13: 9 | J13: Công suất trung bình khi cđ đều | K13: P2 | L13: P2=F2*v1 | M13: 2443.51 | N13: W
A14: 10 | B14: Hệ số ma sát trượt | C14: mu | E14: 0.2 | I14: 10 | J14: Thời gian giảm tốc | K14: t3 | M14: 10 | N14: s
A15: 11 | B15: Hiệu suất truyền động | C15: eta | E15: 0.96 | I15: 11 | J15: Gia tốc khi giảm tốc | K15: a2 | L15: a2=-v1/t3 | M15: -0.011 | N15: m/s^2
A16: 12 | B16: Hệ số dự trữ | C16: k | E16: 1.2 | I16: 12 | J16: Lực khi giảm tốc | K16: Fg2 | L16: Fg2=(M+m)*(mu*g+a2) | M16: 22089 | N16: N
A17: 13 | B17: Gia tốc trọng trường | C17: g | E17: 9.81 | F17: m/s^2 | I17: 13 | J17: Tốc độ trung bình khi giảm tốc | K17: vtb2 | L17: vtb2=-1/2*a2*t3 | M17: 0.055 | N17: m/s
A18: 14 | B18: Lực phát động của động cơ | C18: F | D18: F=(M+m)*(mu*g+a) | E18: 27874.764 | F18: N | I18: 14 | J18: Công suất trung bình khi giảm tốc | K18: P3 | L18: P3=Fg2*vtb2 | M18: 1214.9 | N18: W
A19: 15 | B19: Momen trên trục bánh xe | C19: T | D19: T=F*d/2 | E19: 3484.3455 | F19: Nm | I19: 15 | J19: Thời gian nghỉ | K19: denta t | M19: 30 | N19: s
A20: 16 | B20: Momen trên trục động cơ | C20: Tdc | D20: Tdc=k*T/(eta*i) | E20: 43.55 | F20: Nm | H20: Không tải | I20: 16 | J20: Thời gian tăng tốc | K20: t4 | M20: 2 | N20: s
A21: 17 | B21: Tốc độ góc bánh xe | C21: omega | D21: omega=2*v/d | E21: 0.88 | F21: rad/s | I21: 17 | J21: Tăng đến giá trị vận tốc | K21: v1 | M21: 0.11 | N21: m/s
A22: 18 | B22: Tốc độ quay bánh xe | C22: n | D22: n=(60*omega/2pi) | E22: 8.4 | F22: rpm | I22: 18 | J22: Gia tốc khi tăng tốc | K22: a3 | L22: a3=v1/t4 | M22: 0.055 | N22: m/s^2
A23: 19 | B23: Tốc độ quay động cơ | C23: ndc | D23: ndc=n*i | E23: 840 | F23: rpm | I23: 19 | J23: Lực khi tăng tốc | K23: Ft2 | L23: Ft2=m*(mu*g+a3) | M23: 425.6 | N23: N
A24: 20 | B24: Công suất động cơ cần thiết | C24: P | D24: P=(2pi/60)(Tdc*ndc/eta) | E24: 3990.48 | F24: W | I24: 20 | J24: Tốc độ trung bình khi tăng tốc | K24: vtb3 | L24: vtb3=1/2*a3*t4 | M24: 0.055 | N24: m/s
I25: 21 | J25: Công suất trung bình khi tăng tốc | K25: P4 | L25: P4=Ft2*vtb3 | M25: 23.41 | N25: W
B26: Cần lựa chọn động cơ thỏa mãn | C26: P> | D26: 3990.48 | E26: W | I26: 22 | J26: Thời gian cđ thẳng đều | K26: t5 | M26: 80 | N26: s
B27: Chọn động cơ M3AA 132ME 6 như hình dưới | C27: ndc> | D27: 840 | E27: rpm | I27: 23 | J27: Lực khi cđ đều | K27: F2 | L27: F2=m*mu*g | M27: 413.98 | N27: N
C28: Tdc> | D28: 43.55 | E28: Nm | I28: 24 | J28: Công suất trung bình khi cđ đều | K28: P5 | L28: P5=F2*v1 | M28: 45.54 | N28: W
I29: 25 | J29: Thời gian giảm tốc | K29: t6 | M29: 5 | N29: s
I30: 26 | J30: Gia tốc khi giảm tốc | K30: a4 | L30: a4=-v1/t6 | M30: -0.022 | N30: m/s^2
A31: Thông số động cơ | I31: 27 | J31: Lực khi giảm tốc | K31: Fg2 | L31: Fg2=m*(mu*g+a4) | M31: 409.34 | N31: N
A32: STT | B32: Thông số | C32: Giá trị | D32: Đơn vị | E32: Ký hiệu | I32: 28 | J32: Tốc độ trung bình khi giảm tốc | K32: vtb4 | L32: vtb4=-1/2*a4*t6 | M32: 0.055 | N32: m/s
I33: 29 | J33: Công suất trung bình khi giảm tốc | K33: P6 | L33: P6=Fg2*vtb4 | M33: 22.51 | N33: W
A34: 1 | B34: Công suất định mức | C34: 5.5 | D34: kW | E34: Pđm | I34: 30 | J34: Công suất hiệu dụng của động cơ | K34: Phd | L34: Phd=sqrt((P1^2*t1+P2^2*t2+P3^2*t3+P4^2*t5+P5^2*t6+P6^2*t7)/(t1+t2+t3+t4+t5+t6+T7)) | M34: 1540.12 | N34: W
A35: 2 | B35: Điện áp dây định mức | C35: 400 | D35: V | E35: U1đm | I35: 31 | J35: Tốc độ định mức của động cơ | K35: omega m | L35: omega m=v/r*i=2v*i/d | M35: =2*0.11*100/0.25 -> 88 | N35: rad/s
A36: 3 | B36: Tốc độ định mức | C36: 973 | D36: r/min | E36: nđm | I36: 31 | J36: Momen hiệu dụng ứng với công suất hiệu dụng (Momen định mức) | K36: Thd | L36: Thd=Phd/omega m | M36: =M34/M35 -> 17.501364 | N36: Nm
A37: 4 | B37: Hiệu suất 100% tải | C37: 89.5 | D37: % | E37: eta | I37: 32 | J37: Momen mở máy | K37: Tm | L37: Tm=Fmax*r/(i*eta) =(Fmax*d)/(2*i*eta) | M37: =(E18*E12)/(2*100*0.96) -> 36.295266 | N37: Nm
A38: 5 | B38: Hiệu suất 75% tải | C38: 90.2 | D38: % | I38: 33 | J38: Công suất lựa chọn | K38: Pchon | L38: Pchon=Pdm*kdutru/eta | M38: =M34*1.2/0.96 -> 1925.15 | N38: W
B39: Hiệu suất 50% tải | C39: 89.6 | D39: %
A40: 6 | B40: Hệ số công suất | C40: 0.74 | E40: cosphi
A41: 7 | B41: Dòng điện stator định mức | C41: 12 | D41: A | E41: I1đm
...

Sheet Tinh_toan_x2
A1: TÍNH TOÁN XE CON CẦU TRỤC
J2: Chu kỳ cùng hành trình; số liệu cột M theo ramp tuyến tính để đối chiếu
A4: STT | B4: Thông số | C4: Kí hiệu | D4: Công thức tính | E4: Giá trị | F4: Đơn vị | I4: STT | J4: Thông số | K4: Kí hiệu | L4: Công thức tính | M4: Giá trị | N4: Đơn vị
A5: 1 | B5: Hàng đơn vị của STT trong ds lớp | C5: x | E5: 2 | H5: Có tải | I5: 1 | J5: Thời gian tăng tốc | K5: t1 | M5: 2 | N5: s
A6: 2 | B6: Tải trọng định mức | C6: M | E6: =10000+1111*E5 -> 12222 | F6: kg | I6: 2 | J6: Tăng đến giá trị vận tốc | K6: v1 | M6: =E9 -> 0.12 | N6: m/s
A7: 3 | B7: Khối lượng cơ cấu nâng hạ | C7: m | E7: =200+11*E5 -> 222 | F7: kg | I7: 3 | J7: Gia tốc khi tăng tốc | K7: a1 | L7: a1=v1/t1 | M7: =M6/M5 -> 0.06 | N7: m/s^2
A8: 4 | B8: Chiều cao nâng | C8: h | E8: =10+E5 -> 12 | F8: m | I8: 4 | J8: Lực khi tăng tốc | K8: Ft1 | L8: Ft1=(M+m)*(mu*g+a1) | M8: =(E6+E7+E51)*(E14*E17+M7) -> 25161.768 | N8: N
A9: 5 | B9: Tốc độ tối đa | C9: v | E9: =0.1+E5/100 -> 0.12 | F9: m/s | I9: 5 | J9: Tốc độ trung bình khi tăng tốc | K9: vtb1 | L9: vtb1=s1/t1=1/2*a1*t1 | M9: =M6/2 -> 0.06 | N9: m/s
A10: 6 | B10: Gia tốc cực đại | C10: a | E10: 0.5 | F10: m/s^2 | I10: 6 | J10: Công suất trung bình khi tăng tốc | K10: P1 | L10: P1=Ft1*vtb1 | M10: =M8*M9 -> 1509.7061 | N10: W
A11: 7 | B11: Độ giật cực đại | C11: rô | E11: 2 | F11: m/s^3 | I11: 7 | J11: Thời gian cđ thẳng đều | K11: t2 | M11: 80 | N11: s
A12: 8 | B12: Đường kính bánh xe | C12: d | E12: 0.25 | F12: m | I12: 8 | J12: Lực khi cđ đều | K12: F2 | L12: F2=(M+m)*mu*g | M12: =(E6+E7+E51)*E14*E17 -> 24415.128 | N12: N
A13: 9 | B13: Tỷ số truyền | C13: i | E13: 100 | I13: 9 | J13: Công suất trung bình khi cđ đều | K13: P2 | L13: P2=F2*v1 | M13: =M12*M6 -> 2929.8154 | N13: W
A14: 10 | B14: Hệ số ma sát trượt | C14: mu | E14: 0.2 | I14: 10 | J14: Thời gian giảm tốc | K14: t3 | M14: 10 | N14: s
A15: 11 | B15: Hiệu suất truyền động | C15: eta | E15: 0.96 | I15: 11 | J15: Gia tốc khi giảm tốc | K15: a2 | L15: a2=-v1/t3 | M15: =-M6/M14 -> -0.012 | N15: m/s^2
A16: 12 | B16: Hệ số dự trữ | C16: k | E16: 1.2 | I16: 12 | J16: Lực khi giảm tốc | K16: Fg2 | L16: Fg2=(M+m)*(mu*g+a2) | M16: =(E6+E7+E51)*(E14*E17+M15) -> 24265.8 | N16: N
A17: 13 | B17: Gia tốc trọng trường | C17: g | E17: 9.81 | F17: m/s^2 | I17: 13 | J17: Tốc độ trung bình khi giảm tốc | K17: vtb2 | L17: vtb2=-1/2*a2*t3 | M17: =M6/2 -> 0.06 | N17: m/s
A18: 14 | B18: Lực phát động của động cơ | C18: F | D18: F = (M+m)*(mu*g+a) | E18: =(E6+E7+E51)*(E14*E17+E10) -> 30637.128 | F18: N | I18: 14 | J18: Công suất trung bình khi giảm tốc | K18: P3 | L18: P3=Fg2*vtb2 | M18: =M16*M17 -> 1455.948 | N18: W
A19: 15 | B19: Momen trên trục bánh xe | C19: T | D19: T = F*d/2 | E19: =E18*E12/2 -> 3829.641 | F19: Nm | I19: 15 | J19: Thời gian nghỉ | K19: delta t | M19: 30 | N19: s
A20: 16 | B20: Momen trên trục động cơ | C20: Tdc | D20: Tdc = k*T/(eta*i) | E20: =E16*E19/(E15*E13) -> 47.870512 | F20: Nm | H20: Không tải | I20: 16 | J20: Thời gian tăng tốc | K20: t4 | M20: 2 | N20: s
A21: 17 | B21: Tốc độ góc bánh xe | C21: omega | D21: omega = 2*v/d | E21: =2*E9/E12 -> 0.96 | F21: rad/s | I21: 17 | J21: Tăng đến giá trị vận tốc | K21: v1 | M21: =E9 -> 0.12 | N21: m/s
A22: 18 | B22: Tốc độ quay bánh xe | C22: n | D22: n = (60*omega/2pi) | E22: =60*E21/(2*PI()) -> 9.1673247 | F22: rpm | I22: 18 | J22: Gia tốc khi tăng tốc | K22: a3 | L22: a3=v1/t4 | M22: =M21/M20 -> 0.06 | N22: m/s^2
A23: 19 | B23: Tốc độ quay động cơ | C23: ndc | D23: ndc = n*i | E23: =E22*E13 -> 916.73247 | F23: rpm | I23: 19 | J23: Lực khi tăng tốc | K23: Ft2 | L23: Ft2=m*(mu*g+a3) | M23: =(E7+E51)*(E14*E17+M22) -> 448.884 | N23: N
A24: 20 | B24: Công suất động cơ cần thiết | C24: P | D24: P=(2pi/60)(Tdc*ndc/eta) | E24: =E20*2*PI()*E23/60 -> 4595.5692 | F24: W | I24: 20 | J24: Tốc độ trung bình khi tăng tốc | K24: vtb3 | L24: vtb3=1/2*a3*t4 | M24: =M21/2 -> 0.06 | N24: m/s
I25: 21 | J25: Công suất trung bình khi tăng tốc | K25: P4 | L25: P4=Ft2*vtb3 | M25: =M23*M24 -> 26.93304 | N25: W
D26: Yêu cầu chọn động cơ | I26: 22 | J26: Thời gian cđ thẳng đều | K26: t5 | M26: =M11+(M5+M14-M20-M29)/2 -> 82.5 | N26: s
D27: P > | E27: =MAX(E24,M38) -> 4595.5692 | F27: W | I27: 23 | J27: Lực khi cđ đều | K27: F2 | L27: F2=m*mu*g | M27: =(E7+E51)*E14*E17 -> 435.564 | N27: N
D28: ndc > | E28: =E23 -> 916.73247 | F28: rpm | I28: 24 | J28: Công suất trung bình khi cđ đều | K28: P5 | L28: P5=F2*v1 | M28: =M27*M21 -> 52.26768 | N28: W
D29: Tdc> | E29: =E20 -> 47.870512 | F29: Nm | I29: 25 | J29: Thời gian giảm tốc | K29: t6 | M29: 5 | N29: s
I30: 26 | J30: Gia tốc khi giảm tốc | K30: a4 | L30: a4=-v1/t6 | M30: =-M21/M29 -> -0.024 | N30: m/s^2
A31: THÔNG SỐ ĐỘNG CƠ | I31: 27 | J31: Lực khi giảm tốc | K31: Fg2 | L31: Fg2=m*(mu*g+a4) | M31: =(E7+E51)*(E14*E17+M30) -> 430.236 | N31: N
A32: STT | B32: Thông số | C32: Giá trị | D32: Đơn vị | E32: Ký hiệu | I32: 28 | J32: Tốc độ trung bình khi giảm tốc | K32: vtb4 | L32: vtb4=-1/2*a4*t6 | M32: =M21/2 -> 0.06 | N32: m/s
A33: 1 | B33: Công suất định mức | C33: 5.5 | D33: kW | E33: Pđm | I33: 29 | J33: Công suất trung bình khi giảm tốc | K33: P6 | L33: P6=Fg2*vtb4 | M33: =M31*M32 -> 25.81416 | N33: W
A34: 2 | B34: Điện áp dây định mức | C34: 400 | D34: V | E34: U1đm | I34: 30 | J34: Công suất hiệu dụng trục motor S-curve | K34: Phd | L34: sqrt(∫ P_motor² dt / Tck) | M34: =Chu_ky!B25 -> 1924.6695 | N34: W
A35: 3 | B35: Tốc độ định mức | C35: 973 | D35: r/min | E35: nđm | I35: 31 | J35: Tốc độ góc motor làm việc | K35: omega m | L35: omega m=v/r*i=2v*i/d | M35: =2*E9*E13/E12 -> 96 | N35: rad/s
A36: 4 | B36: Hiệu suất 100% tải | C36: 89.5 | D36: % | E36: eta | I36: 31 | J36: Mô-men RMS motor S-curve | K36: Thd | L36: sqrt(∫ M_motor² dt / Tck) | M36: =Chu_ky!B26 -> 20.973821 | N36: Nm
A37: 5 | B37: Hiệu suất 75% tải | C37: 90.2 | D37: % | I37: 32 | J37: Mô-men yêu cầu đỉnh theo quỹ đạo | K37: Tm | L37: Gồm quán tính rotor; xem Chu_ky | M37: =Chu_ky!B27 -> 35.041031 | N37: Nm
B38: Hiệu suất 50% tải | C38: 89.6 | D38: % | I38: 33 | J38: Công suất hiệu dụng có dự trữ | K38: Pchon | L38: k × P_hd,motor; không chia η thêm | M38: =E16*M34 -> 2309.6034 | N38: W
A39: 6 | B39: Hệ số công suất | C39: 0.74 | E39: cosphi
A40: 7 | B40: Dòng điện stator định mức | C40: 12 | D40: A | E40: I1đm | J40: Công suất RMS theo P trung bình kiểu mẫu | M40: =SQRT((M10^2*M5+M13^2*M11+M18^2*M14+M25^2*M20+M28^2*M26+M33^2*M29)/(M5+M11+M14+M19+M20+M26+M29))/E15 -> 1912.1611 | N40: W
A41: 8 | B41: Dòng điện stator khởi động | C41: =C40*5.8 -> 69.6 | D41: A | E41: Is | J41: Hành trình có tải | M41: =E9*(M11+(M5+M14)/2) -> 10.32 | N41: m
...

Sheet Chu_ky
A1: CHU KỲ x = 2 — S-CURVE VÀ TÍCH PHÂN CÔNG SUẤT
A2: Có tải đi → nghỉ 30 s → không tải về. Khoảng đi và về bằng nhau. P và M tính tại trục motor.
A4: Pha | B4: Δt (s) | C4: Khối lượng (kg) | D4: Chiều | E4: j (m/s³) | F4: a đầu | G4: v đầu | H4: t đầu | I4: a cuối | J4: v cuối | K4: S (m) | L4: ∫P²dt | M4: ∫M²dt | N4: |M| đỉnh
A5: Có tải tăng j+ | B5: =Tinh_toan_x2!E58 -> 0.25 | C5: =Tinh_toan_x2!E7+Tinh_toan_x2!E51+Tinh_toan_x2!E6 -> 12444 | D5: 1 | E5: =Tinh_toan_x2!E9/(Tinh_toan_x2!M5-Tinh_toan_x2!E58)/Tinh_toan_x2!E58 -> 0.27428571 | F5: 0 | G5: 0 | H5: 0 | I5: =F5+E5*B5 -> 0.068571429 | J5: =G5+F5*B5+0.5*E5*B5^2 -> 0.0085714286 | K5: =G5*B5+0.5*F5*B5^2+E5*B5^3/6 -> 0.00071428571 | L5: =SUM(J36:J39) -> 2798.6783 | M5: =SUM(K36:K39) -> 279.37373 | N5: =MAX(ABS(D5*(C5*(Tinh_toan_x2!E14*Tinh_toan_x2!E17+F5)*Tinh_toan_x2!E12/(2*Tinh_toan_x2!E15*Tinh_toan_x2!E13)+(Tinh_toan_x2!C47+Tinh_toan_x2!E52+Tinh_toan_x2!E53/Tinh_toan_x2!E13^2)*2*Tinh_toan_x2!E13/Tinh_toan_x2!E12*F5)),ABS(D5*(C5*(Tinh_toan_x2!E14*Tinh_toan_x2!E17+I5)*Tinh_toan_x2!E12/(2*Tinh_toan_x2!E15*Tinh_toan_x2!E13)+(Tinh_toan_x2!C47+Tinh_toan_x2!E52+Tinh_toan_x2!E53/Tinh_toan_x2!E13^2)*2*Tinh_toan_x2!E13/Tinh_toan_x2!E12*I5))) -> 35.041031
A6: Có tải tăng a | B6: =Tinh_toan_x2!M5-2*Tinh_toan_x2!E58 -> 1.5 | C6: =Tinh_toan_x2!E7+Tinh_toan_x2!E51+Tinh_toan_x2!E6 -> 12444 | D6: 1 | E6: =0 -> 0 | F6: =I5 -> 0.068571429 | G6: =J5 -> 0.0085714286 | H6: =H5+B5 -> 0.25 | I6: =F6+E6*B6 -> 0.068571429 | J6: =G6+F6*B6+0.5*E6*B6^2 -> 0.11142857 | K6: =G6*B6+0.5*F6*B6^2+E6*B6^3/6 -> 0.09 | L6: =SUM(J40:J43) -> 5282764.4 | M6: =SUM(K40:K43) -> 1841.8108 | N6: =MAX(ABS(D6*(C6*(Tinh_toan_x2!E14*Tinh_toan_x2!E17+F6)*Tinh_toan_x2!E12/(2*Tinh_toan_x2!E15*Tinh_toan_x2!E13)+(Tinh_toan_x2!C47+Tinh_toan_x2!E52+Tinh_toan_x2!E53/Tinh_toan_x2!E13^2)*2*Tinh_toan_x2!E13/Tinh_toan_x2!E12*F6)),ABS(D6*(C6*(Tinh_toan_x2!E14*Tinh_toan_x2!E17+I6)*Tinh_toan_x2!E12/(2*Tinh_toan_x2!E15*Tinh_toan_x2!E13)+(Tinh_toan_x2!C47+Tinh_toan_x2!E52+Tinh_toan_x2!E53/Tinh_toan_x2!E13^2)*2*Tinh_toan_x2!E13/Tinh_toan_x2!E12*I6))) -> 35.041031
A7: Có tải tăng j- | B7: =Tinh_toan_x2!E58 -> 0.25 | C7: =Tinh_toan_x2!E7+Tinh_toan_x2!E51+Tinh_toan_x2!E6 -> 12444 | D7: 1 | E7: =-Tinh_toan_x2!E9/(Tinh_toan_x2!M5-Tinh_toan_x2!E58)/Tinh_toan_x2!E58 -> -0.27428571 | F7: =I6 -> 0.068571429 | G7: =J6 -> 0.11142857 | H7: =H6+B6 -> 1.75 | I7: =F7+E7*B7 -> 0 | J7: =G7+F7*B7+0.5*E7*B7^2 -> 0.12 | K7: =G7*B7+0.5*F7*B7^2+E7*B7^3/6 -> 0.029285714 | L7: =SUM(J44:J47) -> 2448924 | M7: =SUM(K44:K47) -> 279.37373 | N7: =MAX(ABS(D7*(C7*(Tinh_toan_x2!E14*Tinh_toan_x2!E17+F7)*Tinh_toan_x2!E12/(2*Tinh_toan_x2!E15*Tinh_toan_x2!E13)+(Tinh_toan_x2!C47+Tinh_toan_x2!E52+Tinh_toan_x2!E53/Tinh_toan_x2!E13^2)*2*Tinh_toan_x2!E13/Tinh_toan_x2!E12*F7)),ABS(D7*(C7*(Tinh_toan_x2!E14*Tinh_toan_x2!E17+I7)*Tinh_toan_x2!E12/(2*Tinh_toan_x2!E15*Tinh_toan_x2!E13)+(Tinh_toan_x2!C47+Tinh_toan_x2!E52+Tinh_toan_x2!E53/Tinh_toan_x2!E13^2)*2*Tinh_toan_x2!E13/Tinh_toan_x2!E12*I7))) -> 35.041031
A8: Có tải đều | B8: =Tinh_toan_x2!M11 -> 80 | C8: =Tinh_toan_x2!E7+Tinh_toan_x2!E51+Tinh_toan_x2!E6 -> 12444 | D8: 1 | E8: =0 -> 0 | F8: =I7 -> 0 | G8: =J7 -> 0.12 | H8: =H7+B7 -> 2 | I8: =F8+E8*B8 -> 0 | J8: =G8+F8*B8+0.5*E8*B8^2 -> 0.12 | K8: =G8*B8+0.5*F8*B8^2+E8*B8^3/6 -> 9.6 | L8: =SUM(J48:J51) -> 7.4512309e+08 | M8: =SUM(K48:K51) -> 80851.03 | N8: =MAX(ABS(D8*(C8*(Tinh_toan_x2!E14*Tinh_toan_x2!E17+F8)*Tinh_toan_x2!E12/(2*Tinh_toan_x2!E15*Tinh_toan_x2!E13)+(Tinh_toan_x2!C47+Tinh_toan_x2!E52+Tinh_toan_x2!E53/Tinh_toan_x2!E13^2)*2*Tinh_toan_x2!E13/Tinh_toan_x2!E12*F8)),ABS(D8*(C8*(Tinh_toan_x2!E14*Tinh_toan_x2!E17+I8)*Tinh_toan_x2!E12/(2*Tinh_toan_x2!E15*Tinh_toan_x2!E13)+(Tinh_toan_x2!C47+Tinh_toan_x2!E52+Tinh_toan_x2!E53/Tinh_toan_x2!E13^2)*2*Tinh_toan_x2!E13/Tinh_toan_x2!E12*I8))) -> 31.790531
A9: Có tải giảm j- | B9: =Tinh_toan_x2!E58 -> 0.25 | C9: =Tinh_toan_x2!E7+Tinh_toan_x2!E51+Tinh_toan_x2!E6 -> 12444 | D9: 1 | E9: =-Tinh_toan_x2!E9/(Tinh_toan_x2!M14-Tinh_toan_x2!E58)/Tinh_toan_x2!E58 -> -0.049230769 | F9: =I8 -> 0 | G9: =J8 -> 0.12 | H9: =H8+B8 -> 82 | I9: =F9+E9*B9 -> -0.012307692 | J9: =G9+F9*B9+0.5*E9*B9^2 -> 0.11846154 | K9: =G9*B9+0.5*F9*B9^2+E9*B9^3/6 -> 0.029871795 | L9: =SUM(J52:J55) -> 2266754.3 | M9: =SUM(K52:K55) -> 248.051 | N9: =MAX(ABS(D9*(C9*(Tinh_toan_x2!E14*Tinh_toan_x2!E17+F9)*Tinh_toan_x2!E12/(2*Tinh_toan_x2!E15*Tinh_toan_x2!E13)+(Tinh_toan_x2!C47+Tinh_toan_x2!E52+Tinh_toan_x2!E53/Tinh_toan_x2!E13^2)*2*Tinh_toan_x2!E13/Tinh_toan_x2!E12*F9)),ABS(D9*(C9*(Tinh_toan_x2!E14*Tinh_toan_x2!E17+I9)*Tinh_toan_x2!E12/(2*Tinh_toan_x2!E15*Tinh_toan_x2!E13)+(Tinh_toan_x2!C47+Tinh_toan_x2!E52+Tinh_toan_x2!E53/Tinh_toan_x2!E13^2)*2*Tinh_toan_x2!E13/Tinh_toan_x2!E12*I9))) -> 31.790531
A10: Có tải giảm a | B10: =Tinh_toan_x2!M14-2*Tinh_toan_x2!E58 -> 9.5 | C10: =Tinh_toan_x2!E7+Tinh_toan_x2!E51+Tinh_toan_x2!E6 -> 12444 | D10: 1 | E10: =0 -> 0 | F10: =I9 -> -0.012307692 | G10: =J9 -> 0.11846154 | H10: =H9+B9 -> 82.25 | I10: =F10+E10*B10 -> -0.012307692 | J10: =G10+F10*B10+0.5*E10*B10^2 -> 0.0015384615 | K10: =G10*B10+0.5*F10*B10^2+E10*B10^3/6 -> 0.57 | L10: =SUM(J56:J59) -> 28062108 | M10: =SUM(K56:K59) -> 9251.8942 | N10: =MAX(ABS(D10*(C10*(Tinh_toan_x2!E14*Tinh_toan_x2!E17+F10)*Tinh_toan_x2!E12/(2*Tinh_toan_x2!E15*Tinh_toan_x2!E13)+(Tinh_toan_x2!C47+Tinh_toan_x2!E52+Tinh_toan_x2!E53/Tinh_toan_x2!E13^2)*2*Tinh_toan_x2!E13/Tinh_toan_x2!E12*F10)),ABS(D10*(C10*(Tinh_toan_x2!E14*Tinh_toan_x2!E17+I10)*Tinh_toan_x2!E12/(2*Tinh_toan_x2!E15*Tinh_toan_x2!E13)+(Tinh_toan_x2!C47+Tinh_toan_x2!E52+Tinh_toan_x2!E53/Tinh_toan_x2!E13^2)*2*Tinh_toan_x2!E13/Tinh_toan_x2!E12*I10))) -> 31.207108
A11: Có tải giảm j+ | B11: =Tinh_toan_x2!E58 -> 0.25 | C11: =Tinh_toan_x2!E7+Tinh_toan_x2!E51+Tinh_toan_x2!E6 -> 12444 | D11: 1 | E11: =Tinh_toan_x2!E9/(Tinh_toan_x2!M14-Tinh_toan_x2!E58)/Tinh_toan_x2!E58 -> 0.049230769 | F11: =I10 -> -0.012307692 | G11: =J10 -> 0.0015384615 | H11: =H10+B10 -> 91.75 | I11: =F11+E11*B11 -> 0 | J11: =G11+F11*B11+0.5*E11*B11^2 -> -8.4567769e-18 | K11: =G11*B11+0.5*F11*B11^2+E11*B11^3/6 -> 0.00012820513 | L11: =SUM(J60:J63) -> 74.222488 | M11: =SUM(K60:K63) -> 248.051 | N11: =MAX(ABS(D11*(C11*(Tinh_toan_x2!E14*Tinh_toan_x2!E17+F11)*Tinh_toan_x2!E12/(2*Tinh_toan_x2!E15*Tinh_toan_x2!E13)+(Tinh_toan_x2!C47+Tinh_toan_x2!E52+Tinh_toan_x2!E53/Tinh_toan_x2!E13^2)*2*Tinh_toan_x2!E13/Tinh_toan_x2!E12*F11)),ABS(D11*(C11*(Tinh_toan_x2!E14*Tinh_toan_x2!E17+I11)*Tinh_toan_x2!E12/(2*Tinh_toan_x2!E15*Tinh_toan_x2!E13)+(Tinh_toan_x2!C47+Tinh_toan_x2!E52+Tinh_toan_x2!E53/Tinh_toan_x2!E13^2)*2*Tinh_toan_x2!E13/Tinh_toan_x2!E12*I11))) -> 31.790531
A12: Nghỉ | B12: =Tinh_toan_x2!M19 -> 30 | C12: =Tinh_toan_x2!E7+Tinh_toan_x2!E51 -> 222 | D12: 0 | E12: =0 -> 0 | F12: 0 | G12: 0 | H12: =H11+B11 -> 92 | I12: =F12+E12*B12 -> 0 | J12: =G12+F12*B12+0.5*E12*B12^2 -> 0 | K12: =G12*B12+0.5*F12*B12^2+E12*B12^3/6 -> 0 | L12: =SUM(J64:J67) -> 0 | M12: =SUM(K64:K67) -> 0 | N12: =MAX(ABS(D12*(C12*(Tinh_toan_x2!E14*Tinh_toan_x2!E17+F12)*Tinh_toan_x2!E12/(2*Tinh_toan_x2!E15*Tinh_toan_x2!E13)+(Tinh_toan_x2!C47+Tinh_toan_x2!E52+Tinh_toan_x2!E53/Tinh_toan_x2!E13^2)*2*Tinh_toan_x2!E13/Tinh_toan_x2!E12*F12)),ABS(D12*(C12*(Tinh_toan_x2!E14*Tinh_toan_x2!E17+I12)*Tinh_toan_x2!E12/(2*Tinh_toan_x2!E15*Tinh_toan_x2!E13)+(Tinh_toan_x2!C47+Tinh_toan_x2!E52+Tinh_toan_x2!E53/Tinh_toan_x2!E13^2)*2*Tinh_toan_x2!E13/Tinh_toan_x2!E12*I12))) -> 0
A13: Không tải tăng j+ | B13: =Tinh_toan_x2!E58 -> 0.25 | C13: =Tinh_toan_x2!E7+Tinh_toan_x2!E51 -> 222 | D13: -1 | E13: =Tinh_toan_x2!E9/(Tinh_toan_x2!M20-Tinh_toan_x2!E58)/Tinh_toan_x2!E58 -> 0.27428571 | F13: 0 | G13: 0 | H13: =H12+B12 -> 122 | I13: =F13+E13*B13 -> 0.068571429 | J13: =G13+F13*B13+0.5*E13*B13^2 -> 0.0085714286 | K13: =G13*B13+0.5*F13*B13^2+E13*B13^3/6 -> 0.00071428571 | L13: =SUM(J68:J71) -> 13.384132 | M13: =SUM(K68:K71) -> 0.77509177 | N13: =MAX(ABS(D13*(C13*(Tinh_toan_x2!E14*Tinh_toan_x2!E17+F13)*Tinh_toan_x2!E12/(2*Tinh_toan_x2!E15*Tinh_toan_x2!E13)+(Tinh_toan_x2!C47+Tinh_toan_x2!E52+Tinh_toan_x2!E53/Tinh_toan_x2!E13^2)*2*Tinh_toan_x2!E13/Tinh_toan_x2!E12*F13)),ABS(D13*(C13*(Tinh_toan_x2!E14*Tinh_toan_x2!E17+I13)*Tinh_toan_x2!E12/(2*Tinh_toan_x2!E15*Tinh_toan_x2!E13)+(Tinh_toan_x2!C47+Tinh_toan_x2!E52+Tinh_toan_x2!E53/Tinh_toan_x2!E13^2)*2*Tinh_toan_x2!E13/Tinh_toan_x2!E12*I13))) -> 2.7263906
A14: Không tải tăng a | B14: =Tinh_toan_x2!M20-2*Tinh_toan_x2!E58 -> 1.5 | C14: =Tinh_toan_x2!E7+Tinh_toan_x2!E51 -> 222 | D14: -1 | E14: =0 -> 0 | F14: =I13 -> 0.068571429 | G14: =J13 -> 0.0085714286 | H14: =H13+B13 -> 122.25 | I14: =F14+E14*B14 -> 0.068571429 | J14: =G14+F14*B14+0.5*E14*B14^2 -> 0.11142857 | K14: =G14*B14+0.5*F14*B14^2+E14*B14^3/6 -> 0.09 | L14: =SUM(J72:J75) -> 31980.382 | M14: =SUM(K72:K75) -> 11.149809 | N14: =MAX(ABS(D14*(C14*(Tinh_toan_x2!E14*Tinh_toan_x2!E17+F14)*Tinh_toan_x2!E12/(2*Tinh_toan_x2!E15*Tinh_toan_x2!E13)+(Tinh_toan_x2!C47+Tinh_toan_x2!E52+Tinh_toan_x2!E53/Tinh_toan_x2!E13^2)*2*Tinh_toan_x2!E13/Tinh_toan_x2!E12*F14)),ABS(D14*(C14*(Tinh_toan_x2!E14*Tinh_toan_x2!E17+I14)*Tinh_toan_x2!E12/(2*Tinh_toan_x2!E15*Tinh_toan_x2!E13)+(Tinh_toan_x2!C47+Tinh_toan_x2!E52+Tinh_toan_x2!E53/Tinh_toan_x2!E13^2)*2*Tinh_toan_x2!E13/Tinh_toan_x2!E12*I14))) -> 2.7263906
A15: Không tải tăng j- | B15: =Tinh_toan_x2!E58 -> 0.25 | C15: =Tinh_toan_x2!E7+Tinh_toan_x2!E51 -> 222 | D15: -1 | E15: =-Tinh_toan_x2!E9/(Tinh_toan_x2!M20-Tinh_toan_x2!E58)/Tinh_toan_x2!E58 -> -0.27428571 | F15: =I14 -> 0.068571429 | G15: =J14 -> 0.11142857 | H15: =H14+B14 -> 123.75 | I15: =F15+E15*B15 -> 0 | J15: =G15+F15*B15+0.5*E15*B15^2 -> 0.12 | K15: =G15*B15+0.5*F15*B15^2+E15*B15^3/6 -> 0.029285714 | L15: =SUM(J76:J79) -> 6612.89 | M15: =SUM(K76:K79) -> 0.77509177 | N15: =MAX(ABS(D15*(C15*(Tinh_toan_x2!E14*Tinh_toan_x2!E17+F15)*Tinh_toan_x2!E12/(2*Tinh_toan_x2!E15*Tinh_toan_x2!E13)+(Tinh_toan_x2!C47+Tinh_toan_x2!E52+Tinh_toan_x2!E53/Tinh_toan_x2!E13^2)*2*Tinh_toan_x2!E13/Tinh_toan_x2!E12*F15)),ABS(D15*(C15*(Tinh_toan_x2!E14*Tinh_toan_x2!E17+I15)*Tinh_toan_x2!E12/(2*Tinh_toan_x2!E15*Tinh_toan_x2!E13)+(Tinh_toan_x2!C47+Tinh_toan_x2!E52+Tinh_toan_x2!E53/Tinh_toan_x2!E13^2)*2*Tinh_toan_x2!E13/Tinh_toan_x2!E12*I15))) -> 2.7263906
A16: Không tải đều | B16: =Tinh_toan_x2!M26 -> 82.5 | C16: =Tinh_toan_x2!E7+Tinh_toan_x2!E51 -> 222 | D16: -1 | E16: =0 -> 0 | F16: =I15 -> 0 | G16: =J15 -> 0.12 | H16: =H15+B15 -> 124 | I16: =F16+E16*B16 -> 0 | J16: =G16+F16*B16+0.5*E16*B16^2 -> 0.12 | K16: =G16*B16+0.5*F16*B16^2+E16*B16^3/6 -> 9.9 | L16: =SUM(J80:J83) -> 244555.78 | M16: =SUM(K80:K83) -> 26.536 | N16: =MAX(ABS(D16*(C16*(Tinh_toan_x2!E14*Tinh_toan_x2!E17+F16)*Tinh_toan_x2!E12/(2*Tinh_toan_x2!E15*Tinh_toan_x2!E13)+(Tinh_toan_x2!C47+Tinh_toan_x2!E52+Tinh_toan_x2!E53/Tinh_toan_x2!E13^2)*2*Tinh_toan_x2!E13/Tinh_toan_x2!E12*F16)),ABS(D16*(C16*(Tinh_toan_x2!E14*Tinh_toan_x2!E17+I16)*Tinh_toan_x2!E12/(2*Tinh_toan_x2!E15*Tinh_toan_x2!E13)+(Tinh_toan_x2!C47+Tinh_toan_x2!E52+Tinh_toan_x2!E53/Tinh_toan_x2!E13^2)*2*Tinh_toan_x2!E13/Tinh_toan_x2!E12*I16))) -> 0.56714063
A17: Không tải giảm j- | B17: =Tinh_toan_x2!E58 -> 0.25 | C17: =Tinh_toan_x2!E7+Tinh_toan_x2!E51 -> 222 | D17: -1 | E17: =-Tinh_toan_x2!E9/(Tinh_toan_x2!M29-Tinh_toan_x2!E58)/Tinh_toan_x2!E58 -> -0.10105263 | F17: =I16 -> 0 | G17: =J16 -> 0.12 | H17: =H16+B16 -> 206.5 | I17: =F17+E17*B17 -> -0.025263158 | J17: =G17+F17*B17+0.5*E17*B17^2 -> 0.11684211 | K17: =G17*B17+0.5*F17*B17^2+E17*B17^3/6 -> 0.029736842 | L17: =SUM(J84:J87) -> 186.62199 | M17: =SUM(K84:K87) -> 0.02035693 | N17: =MAX(ABS(D17*(C17*(Tinh_toan_x2!E14*Tinh_toan_x2!E17+F17)*Tinh_toan_x2!E12/(2*Tinh_toan_x2!E15*Tinh_toan_x2!E13)+(Tinh_toan_x2!C47+Tinh_toan_x2!E52+Tinh_toan_x2!E53/Tinh_toan_x2!E13^2)*2*Tinh_toan_x2!E13/Tinh_toan_x2!E12*F17)),ABS(D17*(C17*(Tinh_toan_x2!E14*Tinh_toan_x2!E17+I17)*Tinh_toan_x2!E12/(2*Tinh_toan_x2!E15*Tinh_toan_x2!E13)+(Tinh_toan_x2!C47+Tinh_toan_x2!E52+Tinh_toan_x2!E53/Tinh_toan_x2!E13^2)*2*Tinh_toan_x2!E13/Tinh_toan_x2!E12*I17))) -> 0.56714063
A18: Không tải giảm a | B18: =Tinh_toan_x2!M29-2*Tinh_toan_x2!E58 -> 4.5 | C18: =Tinh_toan_x2!E7+Tinh_toan_x2!E51 -> 222 | D18: -1 | E18: =0 -> 0 | F18: =I17 -> -0.025263158 | G18: =J17 -> 0.11684211 | H18: =H17+B17 -> 206.75 | I18: =F18+E18*B18 -> -0.025263158 | J18: =G18+F18*B18+0.5*E18*B18^2 -> 0.0031578947 | K18: =G18*B18+0.5*F18*B18^2+E18*B18^3/6 -> 0.27 | L18: =SUM(J88:J91) -> 702.5033 | M18: =SUM(K88:K91) -> 0.23469306 | N18: =MAX(ABS(D18*(C18*(Tinh_toan_x2!E14*Tinh_toan_x2!E17+F18)*Tinh_toan_x2!E12/(2*Tinh_toan_x2!E15*Tinh_toan_x2!E13)+(Tinh_toan_x2!C47+Tinh_toan_x2!E52+Tinh_toan_x2!E53/Tinh_toan_x2!E13^2)*2*Tinh_toan_x2!E13/Tinh_toan_x2!E12*F18)),ABS(D18*(C18*(Tinh_toan_x2!E14*Tinh_toan_x2!E17+I18)*Tinh_toan_x2!E12/(2*Tinh_toan_x2!E15*Tinh_toan_x2!E13)+(Tinh_toan_x2!C47+Tinh_toan_x2!E52+Tinh_toan_x2!E53/Tinh_toan_x2!E13^2)*2*Tinh_toan_x2!E13/Tinh_toan_x2!E12*I18))) -> 0.22837253
A19: Không tải giảm j+ | B19: =Tinh_toan_x2!E58 -> 0.25 | C19: =Tinh_toan_x2!E7+Tinh_toan_x2!E51 -> 222 | D19: -1 | E19: =Tinh_toan_x2!E9/(Tinh_toan_x2!M29-Tinh_toan_x2!E58)/Tinh_toan_x2!E58 -> 0.10105263 | F19: =I18 -> -0.025263158 | G19: =J18 -> 0.0031578947 | H19: =H18+B18 -> 211.25 | I19: =F19+E19*B19 -> 0 | J19: =G19+F19*B19+0.5*E19*B19^2 -> -9.97466e-18 | K19: =G19*B19+0.5*F19*B19^2+E19*B19^3/6 -> 0.00026315789 | L19: =SUM(J92:J95) -> 0.0069348241 | M19: =SUM(K92:K95) -> 0.02035693 | N19: =MAX(ABS(D19*(C19*(Tinh_toan_x2!E14*Tinh_toan_x2!E17+F19)*Tinh_toan_x2!E12/(2*Tinh_toan_x2!E15*Tinh_toan_x2!E13)+(Tinh_toan_x2!C47+Tinh_toan_x2!E52+Tinh_toan_x2!E53/Tinh_toan_x2!E13^2)*2*Tinh_toan_x2!E13/Tinh_toan_x2!E12*F19)),ABS(D19*(C19*(Tinh_toan_x2!E14*Tinh_toan_x2!E17+I19)*Tinh_toan_x2!E12/(2*Tinh_toan_x2!E15*Tinh_toan_x2!E13)+(Tinh_toan_x2!C47+Tinh_toan_x2!E52+Tinh_toan_x2!E53/Tinh_toan_x2!E13^2)*2*Tinh_toan_x2!E13/Tinh_toan_x2!E12*I19))) -> 0.56714063
A22: Thời gian chu kỳ | B22: =SUM(B5:B19) -> 211.5 | C22: s
A23: Quãng đường đi | B23: =SUM(K5:K11) -> 10.32 | C23: m
A24: Quãng đường về | B24: =SUM(K13:K19) -> 10.32 | C24: m
A25: Công suất hiệu dụng motor | B25: =SQRT(SUM(L5:L19)/B22) -> 1924.6695 | C25: W
A26: Mô-men RMS motor | B26: =SQRT(SUM(M5:M19)/B22) -> 20.973821 | C26: N·m
A27: Mô-men motor đỉnh | B27: =MAX(N5:N19) -> 35.041031 | C27: N·m
A28: Gia tốc lớn nhất | B28: =MAX(MAX(F5:F19),-MIN(F5:F19),MAX(I5:I19),-MIN(I5:I19)) -> 0.068571429 | C28: m/s²
A29: Jerk lớn nhất | B29: =MAX(MAX(E5:E19),-MIN(E5:E19)) -> 0.27428571 | C29: m/s³
A30: Công suất hiệu dụng có dự trữ | B30: =B25*Tinh_toan_x2!E16 -> 2309.6034 | C30: W
A31: Kiểm tra quỹ đạo | B31: =IF(AND(B28<=Tinh_toan_x2!E10,B29<=Tinh_toan_x2!E11,ABS(B23-B24)<0.000001,MIN(B5:B19)>=0),"Đạt theo đầu vào","CẦN SỬA") -> Đạt theo đầu vào
A32: Mô hình lực cản khi giảm tốc | B32: =IF(Tinh_toan_x2!E14*Tinh_toan_x2!E17+B28>0,IF(Tinh_toan_x2!E14*Tinh_toan_x2!E17> B28,"Áp dụng công thức thuận","CẦN XÉT HIỆU SUẤT NGƯỢC"),"CẦN XÉT LẠI") -> Áp dụng công thức thuận
A34: Tích phân Gauss 4 điểm cho mỗi pha: chính xác cho P² là đa thức bậc ≤ 6; công suất trung bình không thay cho RMS.
A35: Pha | B35: Trọng số × Δt | C35: u | D35: τ (s) | E35: v dọc đường | F35: a dọc đường | G35: F có dấu | H35: M motor | I35: P motor | J35: P² × dt | K35: M² × dt
A36: =A5 -> Có tải tăng j+ | B36: =B5*0.173927422568727 -> 0.043481856 | C36: 0.069431844 | D36: =B5*C36 -> 0.017357961 | E36: =G5+F5*D36+0.5*E5*D36^2 -> 4.132098e-05 | F36: =F5+E5*D36 -> 0.0047610407 | G36: =D5*C5*(Tinh_toan_x2!E14*Tinh_toan_x2!E17+F36) -> 24474.374 | H36: =G36*Tinh_toan_x2!E12/(2*Tinh_toan_x2!E15*Tinh_toan_x2!E13)+D5*(Tinh_toan_x2!C47+Tinh_toan_x2!E52+Tinh_toan_x2!E53/Tinh_toan_x2!E13^2)*2*Tinh_toan_x2!E13/Tinh_toan_x2!E12*F36 -> 32.016219 | I36: =H36*D5*E36*2*Tinh_toan_x2!E13/Tinh_toan_x2!E12 -> 1.0583532 | J36: =I36^2*B36 -> 0.048704531 | K36: =H36^2*B36 -> 44.570568
A37: =A5 -> Có tải tăng j+ | B37: =B5*0.326072577431273 -> 0.081518144 | C37: 0.33000948 | D37: =B5*C37 -> 0.08250237 | E37: =G5+F5*D37+0.5*E5*D37^2 -> 0.00093348219 | F37: =F5+E5*D37 -> 0.022629221 | G37: =D5*C5*(Tinh_toan_x2!E14*Tinh_toan_x2!E17+F37) -> 24696.726 | H37: =G37*Tinh_toan_x2!E12/(2*Tinh_toan_x2!E15*Tinh_toan_x2!E13)+D5*(Tinh_toan_x2!C47+Tinh_toan_x2!E52+Tinh_toan_x2!E53/Tinh_toan_x2!E13^2)*2*Tinh_toan_x2!E13/Tinh_toan_x2!E12*F37 -> 32.863227 | I37: =H37*D5*E37*2*Tinh_toan_x2!E13/Tinh_toan_x2!E12 -> 24.54179 | J37: =I37^2*B37 -> 49.098333 | K37: =H37^2*B37 -> 88.038919
A38: =A5 -> Có tải tăng j+ | B38: =B5*0.326072577431273 -> 0.081518144 | C38: 0.66999052 | D38: =B5*C38 -> 0.16749763 | E38: =G5+F5*D38+0.5*E5*D38^2 -> 0.0038476054 | F38: =F5+E5*D38 -> 0.045942207 | G38: =D5*C5*(Tinh_toan_x2!E14*Tinh_toan_x2!E17+F38) -> 24986.833 | H38: =G38*Tinh_toan_x2!E12/(2*Tinh_toan_x2!E15*Tinh_toan_x2!E13)+D5*(Tinh_toan_x2!C47+Tinh_toan_x2!E52+Tinh_toan_x2!E53/Tinh_toan_x2!E13^2)*2*Tinh_toan_x2!E13/Tinh_toan_x2!E12*F38 -> 33.968335 | I38: =H38*D5*E38*2*Tinh_toan_x2!E13/Tinh_toan_x2!E12 -> 104.5574 | J38: =I38^2*B38 -> 891.17675 | K38: =H38^2*B38 -> 94.059533
A39: =A5 -> Có tải tăng j+ | B39: =B5*0.173927422568727 -> 0.043481856 | C39: 0.93056816 | D39: =B5*C39 -> 0.23264204 | E39: =G5+F5*D39+0.5*E5*D39^2 -> 0.0074224894 | F39: =F5+E5*D39 -> 0.063810388 | G39: =D5*C5*(Tinh_toan_x2!E14*Tinh_toan_x2!E17+F39) -> 25209.184 | H39: =G39*Tinh_toan_x2!E12/(2*Tinh_toan_x2!E15*Tinh_toan_x2!E13)+D5*(Tinh_toan_x2!C47+Tinh_toan_x2!E52+Tinh_toan_x2!E53/Tinh_toan_x2!E13^2)*2*Tinh_toan_x2!E13/Tinh_toan_x2!E12*F39 -> 34.815343 | I39: =H39*D5*E39*2*Tinh_toan_x2!E13/Tinh_toan_x2!E12 -> 206.73321 | J39: =I39^2*B39 -> 1858.3545 | K39: =H39^2*B39 -> 52.70471
A40: =A6 -> Có tải tăng a | B40: =B6*0.173927422568727 -> 0.26089113 | C40: 0.069431844 | D40: =B6*C40 -> 0.10414777 | E40: =G6+F6*D40+0.5*E6*D40^2 -> 0.01571299 | F40: =F6+E6*D40 -> 0.068571429 | G40: =D6*C6*(Tinh_toan_x2!E14*Tinh_toan_x2!E17+F40) -> 25268.431 | H40: =G40*Tinh_toan_x2!E12/(2*Tinh_toan_x2!E15*Tinh_toan_x2!E13)+D6*(Tinh_toan_x2!C47+Tinh_toan_x2!E52+Tinh_toan_x2!E53/Tinh_toan_x2!E13^2)*2*Tinh_toan_x2!E13/Tinh_toan_x2!E12*F40 -> 35.041031 | I40: =H40*D6*E40*2*Tinh_toan_x2!E13/Tinh_toan_x2!E12 -> 440.47949 | J40: =I40^2*B40 -> 50618.667 | K40: =H40^2*B40 -> 320.34141
A41: =A6 -> Có tải tăng a | B41: =B6*0.326072577431273 -> 0.48910887 | C41: 0.33000948 | D41: =B6*C41 -> 0.49501422 | E41: =G6+F6*D41+0.5*E6*D41^2 -> 0.042515261 | F41: =F6+E6*D41 -> 0.068571429 | G41: =D6*C6*(Tinh_toan_x2!E14*Tinh_toan_x2!E17+F41) -> 25268.431 | H41: =G41*Tinh_toan_x2!E12/(2*Tinh_toan_x2!E15*Tinh_toan_x2!E13)+D6*(Tinh_toan_x2!C47+Tinh_toan_x2!E52+Tinh_toan_x2!E53/Tinh_toan_x2!E13^2)*2*Tinh_toan_x2!E13/Tinh_toan_x2!E12*F41 -> 35.041031 | I41: =H41*D6*E41*2*Tinh_toan_x2!E13/Tinh_toan_x2!E12 -> 1191.8229 | J41: =I41^2*B41 -> 694750.64 | K41: =H41^2*B41 -> 600.564
A42: =A6 -> Có tải tăng a | B42: =B6*0.326072577431273 -> 0.48910887 | C42: 0.66999052 | D42: =B6*C42 -> 1.0049858 | E42: =G6+F6*D42+0.5*E6*D42^2 -> 0.077484739 | F42: =F6+E6*D42 -> 0.068571429 | G42: =D6*C6*(Tinh_toan_x2!E14*Tinh_toan_x2!E17+F42) -> 25268.431 | H42: =G42*Tinh_toan_x2!E12/(2*Tinh_toan_x2!E15*Tinh_toan_x2!E13)+D6*(Tinh_toan_x2!C47+Tinh_toan_x2!E52+Tinh_toan_x2!E53/Tinh_toan_x2!E13^2)*2*Tinh_toan_x2!E13/Tinh_toan_x2!E12*F42 -> 35.041031 | I42: =H42*D6*E42*2*Tinh_toan_x2!E13/Tinh_toan_x2!E12 -> 2172.1161 | J42: =I42^2*B42 -> 2307658.9 | K42: =H42^2*B42 -> 600.564
A43: =A6 -> Có tải tăng a | B43: =B6*0.173927422568727 -> 0.26089113 | C43: 0.93056816 | D43: =B6*C43 -> 1.3958522 | E43: =G6+F6*D43+0.5*E6*D43^2 -> 0.10428701 | F43: =F6+E6*D43 -> 0.068571429 | G43: =D6*C6*(Tinh_toan_x2!E14*Tinh_toan_x2!E17+F43) -> 25268.431 | H43: =G43*Tinh_toan_x2!E12/(2*Tinh_toan_x2!E15*Tinh_toan_x2!E13)+D6*(Tinh_toan_x2!C47+Tinh_toan_x2!E52+Tinh_toan_x2!E53/Tinh_toan_x2!E13^2)*2*Tinh_toan_x2!E13/Tinh_toan_x2!E12*F43 -> 35.041031 | I43: =H43*D6*E43*2*Tinh_toan_x2!E13/Tinh_toan_x2!E12 -> 2923.4595 | J43: =I43^2*B43 -> 2229736.2 | K43: =H43^2*B43 -> 320.34141
A44: =A7 -> Có tải tăng j- | B44: =B7*0.173927422568727 -> 0.043481856 | C44: 0.069431844 | D44: =B7*C44 -> 0.017357961 | E44: =G7+F7*D44+0.5*E7*D44^2 -> 0.11257751 | F44: =F7+E7*D44 -> 0.063810388 | G44: =D7*C7*(Tinh_toan_x2!E14*Tinh_toan_x2!E17+F44) -> 25209.184 | H44: =G44*Tinh_toan_x2!E12/(2*Tinh_toan_x2!E15*Tinh_toan_x2!E13)+D7*(Tinh_toan_x2!C47+Tinh_toan_x2!E52+Tinh_toan_x2!E53/Tinh_toan_x2!E13^2)*2*Tinh_toan_x2!E13/Tinh_toan_x2!E12*F44 -> 34.815343 | I44: =H44*D7*E44*2*Tinh_toan_x2!E13/Tinh_toan_x2!E12 -> 3135.5397 | J44: =I44^2*B44 -> 427496.62 | K44: =H44^2*B44 -> 52.70471
...

Sheet Do_thi
A1: ĐỒ THỊ ĐỦ HAI LƯỢT CÓ TẢI VÀ KHÔNG TẢI
A4: t (s) | B4: v (m/s) | C4: F (N) | D4: P motor (W) | E4: M motor (N·m) | F4: a (m/s²) | G4: j (m/s³) | H4: Pha
A5: =Chu_ky!H5+(Chu_ky!B5*0/10) -> 0 | B5: =Chu_ky!D5*(Chu_ky!G5+Chu_ky!F5*(Chu_ky!B5*0/10)+0.5*Chu_ky!E5*(Chu_ky!B5*0/10)^2) -> 0 | C5: =Chu_ky!C5*(Chu_ky!D5*Tinh_toan_x2!E14*Tinh_toan_x2!E17+F5) -> 24415.128 | D5: =E5*B5*2*Tinh_toan_x2!E13/Tinh_toan_x2!E12 -> 0 | E5: =C5*Tinh_toan_x2!E12/(2*Tinh_toan_x2!E15*Tinh_toan_x2!E13)+(Tinh_toan_x2!C47+Tinh_toan_x2!E52+Tinh_toan_x2!E53/Tinh_toan_x2!E13^2)*2*Tinh_toan_x2!E13/Tinh_toan_x2!E12*F5 -> 31.790531 | F5: =Chu_ky!D5*(Chu_ky!F5+Chu_ky!E5*(Chu_ky!B5*0/10)) -> 0 | G5: =Chu_ky!D5*Chu_ky!E5 -> 0.27428571 | H5: =Chu_ky!A5 -> Có tải tăng j+
A6: =Chu_ky!H5+(Chu_ky!B5*1/10) -> 0.025 | B6: =Chu_ky!D5*(Chu_ky!G5+Chu_ky!F5*(Chu_ky!B5*1/10)+0.5*Chu_ky!E5*(Chu_ky!B5*1/10)^2) -> 8.5714286e-05 | C6: =Chu_ky!C5*(Chu_ky!D5*Tinh_toan_x2!E14*Tinh_toan_x2!E17+F6) -> 24500.458 | D6: =E6*B6*2*Tinh_toan_x2!E13/Tinh_toan_x2!E12 -> 2.2022113 | E6: =C6*Tinh_toan_x2!E12/(2*Tinh_toan_x2!E15*Tinh_toan_x2!E13)+(Tinh_toan_x2!C47+Tinh_toan_x2!E52+Tinh_toan_x2!E53/Tinh_toan_x2!E13^2)*2*Tinh_toan_x2!E13/Tinh_toan_x2!E12*F6 -> 32.115581 | F6: =Chu_ky!D5*(Chu_ky!F5+Chu_ky!E5*(Chu_ky!B5*1/10)) -> 0.0068571429 | G6: =Chu_ky!D5*Chu_ky!E5 -> 0.27428571 | H6: =Chu_ky!A5 -> Có tải tăng j+
A7: =Chu_ky!H5+(Chu_ky!B5*2/10) -> 0.05 | B7: =Chu_ky!D5*(Chu_ky!G5+Chu_ky!F5*(Chu_ky!B5*2/10)+0.5*Chu_ky!E5*(Chu_ky!B5*2/10)^2) -> 0.00034285714 | C7: =Chu_ky!C5*(Chu_ky!D5*Tinh_toan_x2!E14*Tinh_toan_x2!E17+F7) -> 24585.789 | D7: =E7*B7*2*Tinh_toan_x2!E13/Tinh_toan_x2!E12 -> 8.8980017 | E7: =C7*Tinh_toan_x2!E12/(2*Tinh_toan_x2!E15*Tinh_toan_x2!E13)+(Tinh_toan_x2!C47+Tinh_toan_x2!E52+Tinh_toan_x2!E53/Tinh_toan_x2!E13^2)*2*Tinh_toan_x2!E13/Tinh_toan_x2!E12*F7 -> 32.440631 | F7: =Chu_ky!D5*(Chu_ky!F5+Chu_ky!E5*(Chu_ky!B5*2/10)) -> 0.013714286 | G7: =Chu_ky!D5*Chu_ky!E5 -> 0.27428571 | H7: =Chu_ky!A5 -> Có tải tăng j+
A8: =Chu_ky!H5+(Chu_ky!B5*3/10) -> 0.075 | B8: =Chu_ky!D5*(Chu_ky!G5+Chu_ky!F5*(Chu_ky!B5*3/10)+0.5*Chu_ky!E5*(Chu_ky!B5*3/10)^2) -> 0.00077142857 | C8: =Chu_ky!C5*(Chu_ky!D5*Tinh_toan_x2!E14*Tinh_toan_x2!E17+F8) -> 24671.119 | D8: =E8*B8*2*Tinh_toan_x2!E13/Tinh_toan_x2!E12 -> 20.221106 | E8: =C8*Tinh_toan_x2!E12/(2*Tinh_toan_x2!E15*Tinh_toan_x2!E13)+(Tinh_toan_x2!C47+Tinh_toan_x2!E52+Tinh_toan_x2!E53/Tinh_toan_x2!E13^2)*2*Tinh_toan_x2!E13/Tinh_toan_x2!E12*F8 -> 32.765681 | F8: =Chu_ky!D5*(Chu_ky!F5+Chu_ky!E5*(Chu_ky!B5*3/10)) -> 0.020571429 | G8: =Chu_ky!D5*Chu_ky!E5 -> 0.27428571 | H8: =Chu_ky!A5 -> Có tải tăng j+
A9: =Chu_ky!H5+(Chu_ky!B5*4/10) -> 0.1 | B9: =Chu_ky!D5*(Chu_ky!G5+Chu_ky!F5*(Chu_ky!B5*4/10)+0.5*Chu_ky!E5*(Chu_ky!B5*4/10)^2) -> 0.0013714286 | C9: =Chu_ky!C5*(Chu_ky!D5*Tinh_toan_x2!E14*Tinh_toan_x2!E17+F9) -> 24756.449 | D9: =E9*B9*2*Tinh_toan_x2!E13/Tinh_toan_x2!E12 -> 36.305259 | E9: =C9*Tinh_toan_x2!E12/(2*Tinh_toan_x2!E15*Tinh_toan_x2!E13)+(Tinh_toan_x2!C47+Tinh_toan_x2!E52+Tinh_toan_x2!E53/Tinh_toan_x2!E13^2)*2*Tinh_toan_x2!E13/Tinh_toan_x2!E12*F9 -> 33.090731 | F9: =Chu_ky!D5*(Chu_ky!F5+Chu_ky!E5*(Chu_ky!B5*4/10)) -> 0.027428571 | G9: =Chu_ky!D5*Chu_ky!E5 -> 0.27428571 | H9: =Chu_ky!A5 -> Có tải tăng j+
A10: =Chu_ky!H5+(Chu_ky!B5*5/10) -> 0.125 | B10: =Chu_ky!D5*(Chu_ky!G5+Chu_ky!F5*(Chu_ky!B5*5/10)+0.5*Chu_ky!E5*(Chu_ky!B5*5/10)^2) -> 0.0021428571 | C10: =Chu_ky!C5*(Chu_ky!D5*Tinh_toan_x2!E14*Tinh_toan_x2!E17+F10) -> 24841.779 | D10: =E10*B10*2*Tinh_toan_x2!E13/Tinh_toan_x2!E12 -> 57.284196 | E10: =C10*Tinh_toan_x2!E12/(2*Tinh_toan_x2!E15*Tinh_toan_x2!E13)+(Tinh_toan_x2!C47+Tinh_toan_x2!E52+Tinh_toan_x2!E53/Tinh_toan_x2!E13^2)*2*Tinh_toan_x2!E13/Tinh_toan_x2!E12*F10 -> 33.415781 | F10: =Chu_ky!D5*(Chu_ky!F5+Chu_ky!E5*(Chu_ky!B5*5/10)) -> 0.034285714 | G10: =Chu_ky!D5*Chu_ky!E5 -> 0.27428571 | H10: =Chu_ky!A5 -> Có tải tăng j+
A11: =Chu_ky!H5+(Chu_ky!B5*6/10) -> 0.15 | B11: =Chu_ky!D5*(Chu_ky!G5+Chu_ky!F5*(Chu_ky!B5*6/10)+0.5*Chu_ky!E5*(Chu_ky!B5*6/10)^2) -> 0.0030857143 | C11: =Chu_ky!C5*(Chu_ky!D5*Tinh_toan_x2!E14*Tinh_toan_x2!E17+F11) -> 24927.11 | D11: =E11*B11*2*Tinh_toan_x2!E13/Tinh_toan_x2!E12 -> 83.291652 | E11: =C11*Tinh_toan_x2!E12/(2*Tinh_toan_x2!E15*Tinh_toan_x2!E13)+(Tinh_toan_x2!C47+Tinh_toan_x2!E52+Tinh_toan_x2!E53/Tinh_toan_x2!E13^2)*2*Tinh_toan_x2!E13/Tinh_toan_x2!E12*F11 -> 33.740831 | F11: =Chu_ky!D5*(Chu_ky!F5+Chu_ky!E5*(Chu_ky!B5*6/10)) -> 0.041142857 | G11: =Chu_ky!D5*Chu_ky!E5 -> 0.27428571 | H11: =Chu_ky!A5 -> Có tải tăng j+
A12: =Chu_ky!H5+(Chu_ky!B5*7/10) -> 0.175 | B12: =Chu_ky!D5*(Chu_ky!G5+Chu_ky!F5*(Chu_ky!B5*7/10)+0.5*Chu_ky!E5*(Chu_ky!B5*7/10)^2) -> 0.0042 | C12: =Chu_ky!C5*(Chu_ky!D5*Tinh_toan_x2!E14*Tinh_toan_x2!E17+F12) -> 25012.44 | D12: =E12*B12*2*Tinh_toan_x2!E13/Tinh_toan_x2!E12 -> 114.46136 | E12: =C12*Tinh_toan_x2!E12/(2*Tinh_toan_x2!E15*Tinh_toan_x2!E13)+(Tinh_toan_x2!C47+Tinh_toan_x2!E52+Tinh_toan_x2!E53/Tinh_toan_x2!E13^2)*2*Tinh_toan_x2!E13/Tinh_toan_x2!E12*F12 -> 34.065881 | F12: =Chu_ky!D5*(Chu_ky!F5+Chu_ky!E5*(Chu_ky!B5*7/10)) -> 0.048 | G12: =Chu_ky!D5*Chu_ky!E5 -> 0.27428571 | H12: =Chu_ky!A5 -> Có tải tăng j+
A13: =Chu_ky!H5+(Chu_ky!B5*8/10) -> 0.2 | B13: =Chu_ky!D5*(Chu_ky!G5+Chu_ky!F5*(Chu_ky!B5*8/10)+0.5*Chu_ky!E5*(Chu_ky!B5*8/10)^2) -> 0.0054857143 | C13: =Chu_ky!C5*(Chu_ky!D5*Tinh_toan_x2!E14*Tinh_toan_x2!E17+F13) -> 25097.77 | D13: =E13*B13*2*Tinh_toan_x2!E13/Tinh_toan_x2!E12 -> 150.92706 | E13: =C13*Tinh_toan_x2!E12/(2*Tinh_toan_x2!E15*Tinh_toan_x2!E13)+(Tinh_toan_x2!C47+Tinh_toan_x2!E52+Tinh_toan_x2!E53/Tinh_toan_x2!E13^2)*2*Tinh_toan_x2!E13/Tinh_toan_x2!E12*F13 -> 34.390931 | F13: =Chu_ky!D5*(Chu_ky!F5+Chu_ky!E5*(Chu_ky!B5*8/10)) -> 0.054857143 | G13: =Chu_ky!D5*Chu_ky!E5 -> 0.27428571 | H13: =Chu_ky!A5 -> Có tải tăng j+
A14: =Chu_ky!H5+(Chu_ky!B5*9/10) -> 0.225 | B14: =Chu_ky!D5*(Chu_ky!G5+Chu_ky!F5*(Chu_ky!B5*9/10)+0.5*Chu_ky!E5*(Chu_ky!B5*9/10)^2) -> 0.0069428571 | C14: =Chu_ky!C5*(Chu_ky!D5*Tinh_toan_x2!E14*Tinh_toan_x2!E17+F14) -> 25183.101 | D14: =E14*B14*2*Tinh_toan_x2!E13/Tinh_toan_x2!E12 -> 192.82248 | E14: =C14*Tinh_toan_x2!E12/(2*Tinh_toan_x2!E15*Tinh_toan_x2!E13)+(Tinh_toan_x2!C47+Tinh_toan_x2!E52+Tinh_toan_x2!E53/Tinh_toan_x2!E13^2)*2*Tinh_toan_x2!E13/Tinh_toan_x2!E12*F14 -> 34.715981 | F14: =Chu_ky!D5*(Chu_ky!F5+Chu_ky!E5*(Chu_ky!B5*9/10)) -> 0.061714286 | G14: =Chu_ky!D5*Chu_ky!E5 -> 0.27428571 | H14: =Chu_ky!A5 -> Có tải tăng j+
A15: =Chu_ky!H5+(Chu_ky!B5*10/10) -> 0.25 | B15: =Chu_ky!D5*(Chu_ky!G5+Chu_ky!F5*(Chu_ky!B5*10/10)+0.5*Chu_ky!E5*(Chu_ky!B5*10/10)^2) -> 0.0085714286 | C15: =Chu_ky!C5*(Chu_ky!D5*Tinh_toan_x2!E14*Tinh_toan_x2!E17+F15) -> 25268.431 | D15: =E15*B15*2*Tinh_toan_x2!E13/Tinh_toan_x2!E12 -> 240.28136 | E15: =C15*Tinh_toan_x2!E12/(2*Tinh_toan_x2!E15*Tinh_toan_x2!E13)+(Tinh_toan_x2!C47+Tinh_toan_x2!E52+Tinh_toan_x2!E53/Tinh_toan_x2!E13^2)*2*Tinh_toan_x2!E13/Tinh_toan_x2!E12*F15 -> 35.041031 | F15: =Chu_ky!D5*(Chu_ky!F5+Chu_ky!E5*(Chu_ky!B5*10/10)) -> 0.068571429 | G15: =Chu_ky!D5*Chu_ky!E5 -> 0.27428571 | H15: =Chu_ky!A5 -> Có tải tăng j+
A16: =Chu_ky!H6+(Chu_ky!B6*0/10) -> 0.25 | B16: =Chu_ky!D6*(Chu_ky!G6+Chu_ky!F6*(Chu_ky!B6*0/10)+0.5*Chu_ky!E6*(Chu_ky!B6*0/10)^2) -> 0.0085714286 | C16: =Chu_ky!C6*(Chu_ky!D6*Tinh_toan_x2!E14*Tinh_toan_x2!E17+F16) -> 25268.431 | D16: =E16*B16*2*Tinh_toan_x2!E13/Tinh_toan_x2!E12 -> 240.28136 | E16: =C16*Tinh_toan_x2!E12/(2*Tinh_toan_x2!E15*Tinh_toan_x2!E13)+(Tinh_toan_x2!C47+Tinh_toan_x2!E52+Tinh_toan_x2!E53/Tinh_toan_x2!E13^2)*2*Tinh_toan_x2!E13/Tinh_toan_x2!E12*F16 -> 35.041031 | F16: =Chu_ky!D6*(Chu_ky!F6+Chu_ky!E6*(Chu_ky!B6*0/10)) -> 0.068571429 | G16: =Chu_ky!D6*Chu_ky!E6 -> 0 | H16: =Chu_ky!A6 -> Có tải tăng a
A17: =Chu_ky!H6+(Chu_ky!B6*1/10) -> 0.4 | B17: =Chu_ky!D6*(Chu_ky!G6+Chu_ky!F6*(Chu_ky!B6*1/10)+0.5*Chu_ky!E6*(Chu_ky!B6*1/10)^2) -> 0.018857143 | C17: =Chu_ky!C6*(Chu_ky!D6*Tinh_toan_x2!E14*Tinh_toan_x2!E17+F17) -> 25268.431 | D17: =E17*B17*2*Tinh_toan_x2!E13/Tinh_toan_x2!E12 -> 528.61899 | E17: =C17*Tinh_toan_x2!E12/(2*Tinh_toan_x2!E15*Tinh_toan_x2!E13)+(Tinh_toan_x2!C47+Tinh_toan_x2!E52+Tinh_toan_x2!E53/Tinh_toan_x2!E13^2)*2*Tinh_toan_x2!E13/Tinh_toan_x2!E12*F17 -> 35.041031 | F17: =Chu_ky!D6*(Chu_ky!F6+Chu_ky!E6*(Chu_ky!B6*1/10)) -> 0.068571429 | G17: =Chu_ky!D6*Chu_ky!E6 -> 0 | H17: =Chu_ky!A6 -> Có tải tăng a
A18: =Chu_ky!H6+(Chu_ky!B6*2/10) -> 0.55 | B18: =Chu_ky!D6*(Chu_ky!G6+Chu_ky!F6*(Chu_ky!B6*2/10)+0.5*Chu_ky!E6*(Chu_ky!B6*2/10)^2) -> 0.029142857 | C18: =Chu_ky!C6*(Chu_ky!D6*Tinh_toan_x2!E14*Tinh_toan_x2!E17+F18) -> 25268.431 | D18: =E18*B18*2*Tinh_toan_x2!E13/Tinh_toan_x2!E12 -> 816.95661 | E18: =C18*Tinh_toan_x2!E12/(2*Tinh_toan_x2!E15*Tinh_toan_x2!E13)+(Tinh_toan_x2!C47+Tinh_toan_x2!E52+Tinh_toan_x2!E53/Tinh_toan_x2!E13^2)*2*Tinh_toan_x2!E13/Tinh_toan_x2!E12*F18 -> 35.041031 | F18: =Chu_ky!D6*(Chu_ky!F6+Chu_ky!E6*(Chu_ky!B6*2/10)) -> 0.068571429 | G18: =Chu_ky!D6*Chu_ky!E6 -> 0 | H18: =Chu_ky!A6 -> Có tải tăng a
A19: =Chu_ky!H6+(Chu_ky!B6*3/10) -> 0.7 | B19: =Chu_ky!D6*(Chu_ky!G6+Chu_ky!F6*(Chu_ky!B6*3/10)+0.5*Chu_ky!E6*(Chu_ky!B6*3/10)^2) -> 0.039428571 | C19: =Chu_ky!C6*(Chu_ky!D6*Tinh_toan_x2!E14*Tinh_toan_x2!E17+F19) -> 25268.431 | D19: =E19*B19*2*Tinh_toan_x2!E13/Tinh_toan_x2!E12 -> 1105.2942 | E19: =C19*Tinh_toan_x2!E12/(2*Tinh_toan_x2!E15*Tinh_toan_x2!E13)+(Tinh_toan_x2!C47+Tinh_toan_x2!E52+Tinh_toan_x2!E53/Tinh_toan_x2!E13^2)*2*Tinh_toan_x2!E13/Tinh_toan_x2!E12*F19 -> 35.041031 | F19: =Chu_ky!D6*(Chu_ky!F6+Chu_ky!E6*(Chu_ky!B6*3/10)) -> 0.068571429 | G19: =Chu_ky!D6*Chu_ky!E6 -> 0 | H19: =Chu_ky!A6 -> Có tải tăng a
A20: =Chu_ky!H6+(Chu_ky!B6*4/10) -> 0.85 | B20: =Chu_ky!D6*(Chu_ky!G6+Chu_ky!F6*(Chu_ky!B6*4/10)+0.5*Chu_ky!E6*(Chu_ky!B6*4/10)^2) -> 0.049714286 | C20: =Chu_ky!C6*(Chu_ky!D6*Tinh_toan_x2!E14*Tinh_toan_x2!E17+F20) -> 25268.431 | D20: =E20*B20*2*Tinh_toan_x2!E13/Tinh_toan_x2!E12 -> 1393.6319 | E20: =C20*Tinh_toan_x2!E12/(2*Tinh_toan_x2!E15*Tinh_toan_x2!E13)+(Tinh_toan_x2!C47+Tinh_toan_x2!E52+Tinh_toan_x2!E53/Tinh_toan_x2!E13^2)*2*Tinh_toan_x2!E13/Tinh_toan_x2!E12*F20 -> 35.041031 | F20: =Chu_ky!D6*(Chu_ky!F6+Chu_ky!E6*(Chu_ky!B6*4/10)) -> 0.068571429 | G20: =Chu_ky!D6*Chu_ky!E6 -> 0 | H20: =Chu_ky!A6 -> Có tải tăng a
A21: =Chu_ky!H6+(Chu_ky!B6*5/10) -> 1 | B21: =Chu_ky!D6*(Chu_ky!G6+Chu_ky!F6*(Chu_ky!B6*5/10)+0.5*Chu_ky!E6*(Chu_ky!B6*5/10)^2) -> 0.06 | C21: =Chu_ky!C6*(Chu_ky!D6*Tinh_toan_x2!E14*Tinh_toan_x2!E17+F21) -> 25268.431 | D21: =E21*B21*2*Tinh_toan_x2!E13/Tinh_toan_x2!E12 -> 1681.9695 | E21: =C21*Tinh_toan_x2!E12/(2*Tinh_toan_x2!E15*Tinh_toan_x2!E13)+(Tinh_toan_x2!C47+Tinh_toan_x2!E52+Tinh_toan_x2!E53/Tinh_toan_x2!E13^2)*2*Tinh_toan_x2!E13/Tinh_toan_x2!E12*F21 -> 35.041031 | F21: =Chu_ky!D6*(Chu_ky!F6+Chu_ky!E6*(Chu_ky!B6*5/10)) -> 0.068571429 | G21: =Chu_ky!D6*Chu_ky!E6 -> 0 | H21: =Chu_ky!A6 -> Có tải tăng a
A22: =Chu_ky!H6+(Chu_ky!B6*6/10) -> 1.15 | B22: =Chu_ky!D6*(Chu_ky!G6+Chu_ky!F6*(Chu_ky!B6*6/10)+0.5*Chu_ky!E6*(Chu_ky!B6*6/10)^2) -> 0.070285714 | C22: =Chu_ky!C6*(Chu_ky!D6*Tinh_toan_x2!E14*Tinh_toan_x2!E17+F22) -> 25268.431 | D22: =E22*B22*2*Tinh_toan_x2!E13/Tinh_toan_x2!E12 -> 1970.3071 | E22: =C22*Tinh_toan_x2!E12/(2*Tinh_toan_x2!E15*Tinh_toan_x2!E13)+(Tinh_toan_x2!C47+Tinh_toan_x2!E52+Tinh_toan_x2!E53/Tinh_toan_x2!E13^2)*2*Tinh_toan_x2!E13/Tinh_toan_x2!E12*F22 -> 35.041031 | F22: =Chu_ky!D6*(Chu_ky!F6+Chu_ky!E6*(Chu_ky!B6*6/10)) -> 0.068571429 | G22: =Chu_ky!D6*Chu_ky!E6 -> 0 | H22: =Chu_ky!A6 -> Có tải tăng a
A23: =Chu_ky!H6+(Chu_ky!B6*7/10) -> 1.3 | B23: =Chu_ky!D6*(Chu_ky!G6+Chu_ky!F6*(Chu_ky!B6*7/10)+0.5*Chu_ky!E6*(Chu_ky!B6*7/10)^2) -> 0.080571429 | C23: =Chu_ky!C6*(Chu_ky!D6*Tinh_toan_x2!E14*Tinh_toan_x2!E17+F23) -> 25268.431 | D23: =E23*B23*2*Tinh_toan_x2!E13/Tinh_toan_x2!E12 -> 2258.6448 | E23: =C23*Tinh_toan_x2!E12/(2*Tinh_toan_x2!E15*Tinh_toan_x2!E13)+(Tinh_toan_x2!C47+Tinh_toan_x2!E52+Tinh_toan_x2!E53/Tinh_toan_x2!E13^2)*2*Tinh_toan_x2!E13/Tinh_toan_x2!E12*F23 -> 35.041031 | F23: =Chu_ky!D6*(Chu_ky!F6+Chu_ky!E6*(Chu_ky!B6*7/10)) -> 0.068571429 | G23: =Chu_ky!D6*Chu_ky!E6 -> 0 | H23: =Chu_ky!A6 -> Có tải tăng a
A24: =Chu_ky!H6+(Chu_ky!B6*8/10) -> 1.45 | B24: =Chu_ky!D6*(Chu_ky!G6+Chu_ky!F6*(Chu_ky!B6*8/10)+0.5*Chu_ky!E6*(Chu_ky!B6*8/10)^2) -> 0.090857143 | C24: =Chu_ky!C6*(Chu_ky!D6*Tinh_toan_x2!E14*Tinh_toan_x2!E17+F24) -> 25268.431 | D24: =E24*B24*2*Tinh_toan_x2!E13/Tinh_toan_x2!E12 -> 2546.9824 | E24: =C24*Tinh_toan_x2!E12/(2*Tinh_toan_x2!E15*Tinh_toan_x2!E13)+(Tinh_toan_x2!C47+Tinh_toan_x2!E52+Tinh_toan_x2!E53/Tinh_toan_x2!E13^2)*2*Tinh_toan_x2!E13/Tinh_toan_x2!E12*F24 -> 35.041031 | F24: =Chu_ky!D6*(Chu_ky!F6+Chu_ky!E6*(Chu_ky!B6*8/10)) -> 0.068571429 | G24: =Chu_ky!D6*Chu_ky!E6 -> 0 | H24: =Chu_ky!A6 -> Có tải tăng a
A25: =Chu_ky!H6+(Chu_ky!B6*9/10) -> 1.6 | B25: =Chu_ky!D6*(Chu_ky!G6+Chu_ky!F6*(Chu_ky!B6*9/10)+0.5*Chu_ky!E6*(Chu_ky!B6*9/10)^2) -> 0.10114286 | C25: =Chu_ky!C6*(Chu_ky!D6*Tinh_toan_x2!E14*Tinh_toan_x2!E17+F25) -> 25268.431 | D25: =E25*B25*2*Tinh_toan_x2!E13/Tinh_toan_x2!E12 -> 2835.32 | E25: =C25*Tinh_toan_x2!E12/(2*Tinh_toan_x2!E15*Tinh_toan_x2!E13)+(Tinh_toan_x2!C47+Tinh_toan_x2!E52+Tinh_toan_x2!E53/Tinh_toan_x2!E13^2)*2*Tinh_toan_x2!E13/Tinh_toan_x2!E12*F25 -> 35.041031 | F25: =Chu_ky!D6*(Chu_ky!F6+Chu_ky!E6*(Chu_ky!B6*9/10)) -> 0.068571429 | G25: =Chu_ky!D6*Chu_ky!E6 -> 0 | H25: =Chu_ky!A6 -> Có tải tăng a
A26: =Chu_ky!H6+(Chu_ky!B6*10/10) -> 1.75 | B26: =Chu_ky!D6*(Chu_ky!G6+Chu_ky!F6*(Chu_ky!B6*10/10)+0.5*Chu_ky!E6*(Chu_ky!B6*10/10)^2) -> 0.11142857 | C26: =Chu_ky!C6*(Chu_ky!D6*Tinh_toan_x2!E14*Tinh_toan_x2!E17+F26) -> 25268.431 | D26: =E26*B26*2*Tinh_toan_x2!E13/Tinh_toan_x2!E12 -> 3123.6576 | E26: =C26*Tinh_toan_x2!E12/(2*Tinh_toan_x2!E15*Tinh_toan_x2!E13)+(Tinh_toan_x2!C47+Tinh_toan_x2!E52+Tinh_toan_x2!E53/Tinh_toan_x2!E13^2)*2*Tinh_toan_x2!E13/Tinh_toan_x2!E12*F26 -> 35.041031 | F26: =Chu_ky!D6*(Chu_ky!F6+Chu_ky!E6*(Chu_ky!B6*10/10)) -> 0.068571429 | G26: =Chu_ky!D6*Chu_ky!E6 -> 0 | H26: =Chu_ky!A6 -> Có tải tăng a
A27: =Chu_ky!H7+(Chu_ky!B7*0/10) -> 1.75 | B27: =Chu_ky!D7*(Chu_ky!G7+Chu_ky!F7*(Chu_ky!B7*0/10)+0.5*Chu_ky!E7*(Chu_ky!B7*0/10)^2) -> 0.11142857 | C27: =Chu_ky!C7*(Chu_ky!D7*Tinh_toan_x2!E14*Tinh_toan_x2!E17+F27) -> 25268.431 | D27: =E27*B27*2*Tinh_toan_x2!E13/Tinh_toan_x2!E12 -> 3123.6576 | E27: =C27*Tinh_toan_x2!E12/(2*Tinh_toan_x2!E15*Tinh_toan_x2!E13)+(Tinh_toan_x2!C47+Tinh_toan_x2!E52+Tinh_toan_x2!E53/Tinh_toan_x2!E13^2)*2*Tinh_toan_x2!E13/Tinh_toan_x2!E12*F27 -> 35.041031 | F27: =Chu_ky!D7*(Chu_ky!F7+Chu_ky!E7*(Chu_ky!B7*0/10)) -> 0.068571429 | G27: =Chu_ky!D7*Chu_ky!E7 -> -0.27428571 | H27: =Chu_ky!A7 -> Có tải tăng j-
A28: =Chu_ky!H7+(Chu_ky!B7*1/10) -> 1.775 | B28: =Chu_ky!D7*(Chu_ky!G7+Chu_ky!F7*(Chu_ky!B7*1/10)+0.5*Chu_ky!E7*(Chu_ky!B7*1/10)^2) -> 0.11305714 | C28: =Chu_ky!C7*(Chu_ky!D7*Tinh_toan_x2!E14*Tinh_toan_x2!E17+F28) -> 25183.101 | D28: =E28*B28*2*Tinh_toan_x2!E13/Tinh_toan_x2!E12 -> 3139.9117 | E28: =C28*Tinh_toan_x2!E12/(2*Tinh_toan_x2!E15*Tinh_toan_x2!E13)+(Tinh_toan_x2!C47+Tinh_toan_x2!E52+Tinh_toan_x2!E53/Tinh_toan_x2!E13^2)*2*Tinh_toan_x2!E13/Tinh_toan_x2!E12*F28 -> 34.715981 | F28: =Chu_ky!D7*(Chu_ky!F7+Chu_ky!E7*(Chu_ky!B7*1/10)) -> 0.061714286 | G28: =Chu_ky!D7*Chu_ky!E7 -> -0.27428571 | H28: =Chu_ky!A7 -> Có tải tăng j-
A29: =Chu_ky!H7+(Chu_ky!B7*2/10) -> 1.8 | B29: =Chu_ky!D7*(Chu_ky!G7+Chu_ky!F7*(Chu_ky!B7*2/10)+0.5*Chu_ky!E7*(Chu_ky!B7*2/10)^2) -> 0.11451429 | C29: =Chu_ky!C7*(Chu_ky!D7*Tinh_toan_x2!E14*Tinh_toan_x2!E17+F29) -> 25097.77 | D29: =E29*B29*2*Tinh_toan_x2!E13/Tinh_toan_x2!E12 -> 3150.6023 | E29: =C29*Tinh_toan_x2!E12/(2*Tinh_toan_x2!E15*Tinh_toan_x2!E13)+(Tinh_toan_x2!C47+Tinh_toan_x2!E52+Tinh_toan_x2!E53/Tinh_toan_x2!E13^2)*2*Tinh_toan_x2!E13/Tinh_toan_x2!E12*F29 -> 34.390931 | F29: =Chu_ky!D7*(Chu_ky!F7+Chu_ky!E7*(Chu_ky!B7*2/10)) -> 0.054857143 | G29: =Chu_ky!D7*Chu_ky!E7 -> -0.27428571 | H29: =Chu_ky!A7 -> Có tải tăng j-
A30: =Chu_ky!H7+(Chu_ky!B7*3/10) -> 1.825 | B30: =Chu_ky!D7*(Chu_ky!G7+Chu_ky!F7*(Chu_ky!B7*3/10)+0.5*Chu_ky!E7*(Chu_ky!B7*3/10)^2) -> 0.1158 | C30: =Chu_ky!C7*(Chu_ky!D7*Tinh_toan_x2!E14*Tinh_toan_x2!E17+F30) -> 25012.44 | D30: =E30*B30*2*Tinh_toan_x2!E13/Tinh_toan_x2!E12 -> 3155.8632 | E30: =C30*Tinh_toan_x2!E12/(2*Tinh_toan_x2!E15*Tinh_toan_x2!E13)+(Tinh_toan_x2!C47+Tinh_toan_x2!E52+Tinh_toan_x2!E53/Tinh_toan_x2!E13^2)*2*Tinh_toan_x2!E13/Tinh_toan_x2!E12*F30 -> 34.065881 | F30: =Chu_ky!D7*(Chu_ky!F7+Chu_ky!E7*(Chu_ky!B7*3/10)) -> 0.048 | G30: =Chu_ky!D7*Chu_ky!E7 -> -0.27428571 | H30: =Chu_ky!A7 -> Có tải tăng j-
A31: =Chu_ky!H7+(Chu_ky!B7*4/10) -> 1.85 | B31: =Chu_ky!D7*(Chu_ky!G7+Chu_ky!F7*(Chu_ky!B7*4/10)+0.5*Chu_ky!E7*(Chu_ky!B7*4/10)^2) -> 0.11691429 | C31: =Chu_ky!C7*(Chu_ky!D7*Tinh_toan_x2!E14*Tinh_toan_x2!E17+F31) -> 24927.11 | D31: =E31*B31*2*Tinh_toan_x2!E13/Tinh_toan_x2!E12 -> 3155.8281 | E31: =C31*Tinh_toan_x2!E12/(2*Tinh_toan_x2!E15*Tinh_toan_x2!E13)+(Tinh_toan_x2!C47+Tinh_toan_x2!E52+Tinh_toan_x2!E53/Tinh_toan_x2!E13^2)*2*Tinh_toan_x2!E13/Tinh_toan_x2!E12*F31 -> 33.740831 | F31: =Chu_ky!D7*(Chu_ky!F7+Chu_ky!E7*(Chu_ky!B7*4/10)) -> 0.041142857 | G31: =Chu_ky!D7*Chu_ky!E7 -> -0.27428571 | H31: =Chu_ky!A7 -> Có tải tăng j-
A32: =Chu_ky!H7+(Chu_ky!B7*5/10) -> 1.875 | B32: =Chu_ky!D7*(Chu_ky!G7+Chu_ky!F7*(Chu_ky!B7*5/10)+0.5*Chu_ky!E7*(Chu_ky!B7*5/10)^2) -> 0.11785714 | C32: =Chu_ky!C7*(Chu_ky!D7*Tinh_toan_x2!E14*Tinh_toan_x2!E17+F32) -> 24841.779 | D32: =E32*B32*2*Tinh_toan_x2!E13/Tinh_toan_x2!E12 -> 3150.6308 | E32: =C32*Tinh_toan_x2!E12/(2*Tinh_toan_x2!E15*Tinh_toan_x2!E13)+(Tinh_toan_x2!C47+Tinh_toan_x2!E52+Tinh_toan_x2!E53/Tinh_toan_x2!E13^2)*2*Tinh_toan_x2!E13/Tinh_toan_x2!E12*F32 -> 33.415781 | F32: =Chu_ky!D7*(Chu_ky!F7+Chu_ky!E7*(Chu_ky!B7*5/10)) -> 0.034285714 | G32: =Chu_ky!D7*Chu_ky!E7 -> -0.27428571 | H32: =Chu_ky!A7 -> Có tải tăng j-
A33: =Chu_ky!H7+(Chu_ky!B7*6/10) -> 1.9 | B33: =Chu_ky!D7*(Chu_ky!G7+Chu_ky!F7*(Chu_ky!B7*6/10)+0.5*Chu_ky!E7*(Chu_ky!B7*6/10)^2) -> 0.11862857 | C33: =Chu_ky!C7*(Chu_ky!D7*Tinh_toan_x2!E14*Tinh_toan_x2!E17+F33) -> 24756.449 | D33: =E33*B33*2*Tinh_toan_x2!E13/Tinh_toan_x2!E12 -> 3140.4049 | E33: =C33*Tinh_toan_x2!E12/(2*Tinh_toan_x2!E15*Tinh_toan_x2!E13)+(Tinh_toan_x2!C47+Tinh_toan_x2!E52+Tinh_toan_x2!E53/Tinh_toan_x2!E13^2)*2*Tinh_toan_x2!E13/Tinh_toan_x2!E12*F33 -> 33.090731 | F33: =Chu_ky!D7*(Chu_ky!F7+Chu_ky!E7*(Chu_ky!B7*6/10)) -> 0.027428571 | G33: =Chu_ky!D7*Chu_ky!E7 -> -0.27428571 | H33: =Chu_ky!A7 -> Có tải tăng j-
A34: =Chu_ky!H7+(Chu_ky!B7*7/10) -> 1.925 | B34: =Chu_ky!D7*(Chu_ky!G7+Chu_ky!F7*(Chu_ky!B7*7/10)+0.5*Chu_ky!E7*(Chu_ky!B7*7/10)^2) -> 0.11922857 | C34: =Chu_ky!C7*(Chu_ky!D7*Tinh_toan_x2!E14*Tinh_toan_x2!E17+F34) -> 24671.119 | D34: =E34*B34*2*Tinh_toan_x2!E13/Tinh_toan_x2!E12 -> 3125.2843 | E34: =C34*Tinh_toan_x2!E12/(2*Tinh_toan_x2!E15*Tinh_toan_x2!E13)+(Tinh_toan_x2!C47+Tinh_toan_x2!E52+Tinh_toan_x2!E53/Tinh_toan_x2!E13^2)*2*Tinh_toan_x2!E13/Tinh_toan_x2!E12*F34 -> 32.765681 | F34: =Chu_ky!D7*(Chu_ky!F7+Chu_ky!E7*(Chu_ky!B7*7/10)) -> 0.020571429 | G34: =Chu_ky!D7*Chu_ky!E7 -> -0.27428571 | H34: =Chu_ky!A7 -> Có tải tăng j-
A35: =Chu_ky!H7+(Chu_ky!B7*8/10) -> 1.95 | B35: =Chu_ky!D7*(Chu_ky!G7+Chu_ky!F7*(Chu_ky!B7*8/10)+0.5*Chu_ky!E7*(Chu_ky!B7*8/10)^2) -> 0.11965714 | C35: =Chu_ky!C7*(Chu_ky!D7*Tinh_toan_x2!E14*Tinh_toan_x2!E17+F35) -> 24585.789 | D35: =E35*B35*2*Tinh_toan_x2!E13/Tinh_toan_x2!E12 -> 3105.4026 | E35: =C35*Tinh_toan_x2!E12/(2*Tinh_toan_x2!E15*Tinh_toan_x2!E13)+(Tinh_toan_x2!C47+Tinh_toan_x2!E52+Tinh_toan_x2!E53/Tinh_toan_x2!E13^2)*2*Tinh_toan_x2!E13/Tinh_toan_x2!E12*F35 -> 32.440631 | F35: =Chu_ky!D7*(Chu_ky!F7+Chu_ky!E7*(Chu_ky!B7*8/10)) -> 0.013714286 | G35: =Chu_ky!D7*Chu_ky!E7 -> -0.27428571 | H35: =Chu_ky!A7 -> Có tải tăng j-
A36: =Chu_ky!H7+(Chu_ky!B7*9/10) -> 1.975 | B36: =Chu_ky!D7*(Chu_ky!G7+Chu_ky!F7*(Chu_ky!B7*9/10)+0.5*Chu_ky!E7*(Chu_ky!B7*9/10)^2) -> 0.11991429 | C36: =Chu_ky!C7*(Chu_ky!D7*Tinh_toan_x2!E14*Tinh_toan_x2!E17+F36) -> 24500.458 | D36: =E36*B36*2*Tinh_toan_x2!E13/Tinh_toan_x2!E12 -> 3080.8936 | E36: =C36*Tinh_toan_x2!E12/(2*Tinh_toan_x2!E15*Tinh_toan_x2!E13)+(Tinh_toan_x2!C47+Tinh_toan_x2!E52+Tinh_toan_x2!E53/Tinh_toan_x2!E13^2)*2*Tinh_toan_x2!E13/Tinh_toan_x2!E12*F36 -> 32.115581 | F36: =Chu_ky!D7*(Chu_ky!F7+Chu_ky!E7*(Chu_ky!B7*9/10)) -> 0.0068571429 | G36: =Chu_ky!D7*Chu_ky!E7 -> -0.27428571 | H36: =Chu_ky!A7 -> Có tải tăng j-
A37: =Chu_ky!H7+(Chu_ky!B7*10/10) -> 2 | B37: =Chu_ky!D7*(Chu_ky!G7+Chu_ky!F7*(Chu_ky!B7*10/10)+0.5*Chu_ky!E7*(Chu_ky!B7*10/10)^2) -> 0.12 | C37: =Chu_ky!C7*(Chu_ky!D7*Tinh_toan_x2!E14*Tinh_toan_x2!E17+F37) -> 24415.128 | D37: =E37*B37*2*Tinh_toan_x2!E13/Tinh_toan_x2!E12 -> 3051.891 | E37: =C37*Tinh_toan_x2!E12/(2*Tinh_toan_x2!E15*Tinh_toan_x2!E13)+(Tinh_toan_x2!C47+Tinh_toan_x2!E52+Tinh_toan_x2!E53/Tinh_toan_x2!E13^2)*2*Tinh_toan_x2!E13/Tinh_toan_x2!E12*F37 -> 31.790531 | F37: =Chu_ky!D7*(Chu_ky!F7+Chu_ky!E7*(Chu_ky!B7*10/10)) -> 0 | G37: =Chu_ky!D7*Chu_ky!E7 -> -0.27428571 | H37: =Chu_ky!A7 -> Có tải tăng j-
A38: =Chu_ky!H8+(Chu_ky!B8*0/10) -> 2 | B38: =Chu_ky!D8*(Chu_ky!G8+Chu_ky!F8*(Chu_ky!B8*0/10)+0.5*Chu_ky!E8*(Chu_ky!B8*0/10)^2) -> 0.12 | C38: =Chu_ky!C8*(Chu_ky!D8*Tinh_toan_x2!E14*Tinh_toan_x2!E17+F38) -> 24415.128 | D38: =E38*B38*2*Tinh_toan_x2!E13/Tinh_toan_x2!E12 -> 3051.891 | E38: =C38*Tinh_toan_x2!E12/(2*Tinh_toan_x2!E15*Tinh_toan_x2!E13)+(Tinh_toan_x2!C47+Tinh_toan_x2!E52+Tinh_toan_x2!E53/Tinh_toan_x2!E13^2)*2*Tinh_toan_x2!E13/Tinh_toan_x2!E12*F38 -> 31.790531 | F38: =Chu_ky!D8*(Chu_ky!F8+Chu_ky!E8*(Chu_ky!B8*0/10)) -> 0 | G38: =Chu_ky!D8*Chu_ky!E8 -> 0 | H38: =Chu_ky!A8 -> Có tải đều
A39: =Chu_ky!H8+(Chu_ky!B8*1/10) -> 10 | B39: =Chu_ky!D8*(Chu_ky!G8+Chu_ky!F8*(Chu_ky!B8*1/10)+0.5*Chu_ky!E8*(Chu_ky!B8*1/10)^2) -> 0.12 | C39: =Chu_ky!C8*(Chu_ky!D8*Tinh_toan_x2!E14*Tinh_toan_x2!E17+F39) -> 24415.128 | D39: =E39*B39*2*Tinh_toan_x2!E13/Tinh_toan_x2!E12 -> 3051.891 | E39: =C39*Tinh_toan_x2!E12/(2*Tinh_toan_x2!E15*Tinh_toan_x2!E13)+(Tinh_toan_x2!C47+Tinh_toan_x2!E52+Tinh_toan_x2!E53/Tinh_toan_x2!E13^2)*2*Tinh_toan_x2!E13/Tinh_toan_x2!E12*F39 -> 31.790531 | F39: =Chu_ky!D8*(Chu_ky!F8+Chu_ky!E8*(Chu_ky!B8*1/10)) -> 0 | G39: =Chu_ky!D8*Chu_ky!E8 -> 0 | H39: =Chu_ky!A8 -> Có tải đều
A40: =Chu_ky!H8+(Chu_ky!B8*2/10) -> 18 | B40: =Chu_ky!D8*(Chu_ky!G8+Chu_ky!F8*(Chu_ky!B8*2/10)+0.5*Chu_ky!E8*(Chu_ky!B8*2/10)^2) -> 0.12 | C40: =Chu_ky!C8*(Chu_ky!D8*Tinh_toan_x2!E14*Tinh_toan_x2!E17+F40) -> 24415.128 | D40: =E40*B40*2*Tinh_toan_x2!E13/Tinh_toan_x2!E12 -> 3051.891 | E40: =C40*Tinh_toan_x2!E12/(2*Tinh_toan_x2!E15*Tinh_toan_x2!E13)+(Tinh_toan_x2!C47+Tinh_toan_x2!E52+Tinh_toan_x2!E53/Tinh_toan_x2!E13^2)*2*Tinh_toan_x2!E13/Tinh_toan_x2!E12*F40 -> 31.790531 | F40: =Chu_ky!D8*(Chu_ky!F8+Chu_ky!E8*(Chu_ky!B8*2/10)) -> 0 | G40: =Chu_ky!D8*Chu_ky!E8 -> 0 | H40: =Chu_ky!A8 -> Có tải đều
A41: =Chu_ky!H8+(Chu_ky!B8*3/10) -> 26 | B41: =Chu_ky!D8*(Chu_ky!G8+Chu_ky!F8*(Chu_ky!B8*3/10)+0.5*Chu_ky!E8*(Chu_ky!B8*3/10)^2) -> 0.12 | C41: =Chu_ky!C8*(Chu_ky!D8*Tinh_toan_x2!E14*Tinh_toan_x2!E17+F41) -> 24415.128 | D41: =E41*B41*2*Tinh_toan_x2!E13/Tinh_toan_x2!E12 -> 3051.891 | E41: =C41*Tinh_toan_x2!E12/(2*Tinh_toan_x2!E15*Tinh_toan_x2!E13)+(Tinh_toan_x2!C47+Tinh_toan_x2!E52+Tinh_toan_x2!E53/Tinh_toan_x2!E13^2)*2*Tinh_toan_x2!E13/Tinh_toan_x2!E12*F41 -> 31.790531 | F41: =Chu_ky!D8*(Chu_ky!F8+Chu_ky!E8*(Chu_ky!B8*3/10)) -> 0 | G41: =Chu_ky!D8*Chu_ky!E8 -> 0 | H41: =Chu_ky!A8 -> Có tải đều
A42: =Chu_ky!H8+(Chu_ky!B8*4/10) -> 34 | B42: =Chu_ky!D8*(Chu_ky!G8+Chu_ky!F8*(Chu_ky!B8*4/10)+0.5*Chu_ky!E8*(Chu_ky!B8*4/10)^2) -> 0.12 | C42: =Chu_ky!C8*(Chu_ky!D8*Tinh_toan_x2!E14*Tinh_toan_x2!E17+F42) -> 24415.128 | D42: =E42*B42*2*Tinh_toan_x2!E13/Tinh_toan_x2!E12 -> 3051.891 | E42: =C42*Tinh_toan_x2!E12/(2*Tinh_toan_x2!E15*Tinh_toan_x2!E13)+(Tinh_toan_x2!C47+Tinh_toan_x2!E52+Tinh_toan_x2!E53/Tinh_toan_x2!E13^2)*2*Tinh_toan_x2!E13/Tinh_toan_x2!E12*F42 -> 31.790531 | F42: =Chu_ky!D8*(Chu_ky!F8+Chu_ky!E8*(Chu_ky!B8*4/10)) -> 0 | G42: =Chu_ky!D8*Chu_ky!E8 -> 0 | H42: =Chu_ky!A8 -> Có tải đều
...

Sheet Thiet_bi
A1: KIỂM NGHIỆM ĐỘNG CƠ VÀ THIẾT BỊ THEO x = 2
A4: Hạng mục | B4: Kết quả / yêu cầu | C4: Đơn vị | D4: Cơ sở và trạng thái
A5: Động cơ theo sheet x=1 | B5: M3AA 132ME 6 | D5: Số liệu kế thừa mẫu, chưa xác minh lại catalog
A6: Công suất định mức | B6: =Tinh_toan_x2!C33 -> 5.5 | C6: kW | D6: Motor tham khảo 5,5 kW
A7: Công suất thiết kế tải tịnh tiến | B7: =Tinh_toan_x2!E24/1000 -> 4.5955692 | C7: kW | D7: Hiệu suất cơ khí chỉ dùng một lần
A8: Công suất hiệu dụng S-curve | B8: =Chu_ky!B25/1000 -> 1.9246695 | C8: kW | D8: Tích phân toàn chu kỳ, đã gồm rotor
A9: Mô-men danh định | B9: =Tinh_toan_x2!C42 -> 53.9 | C9: N·m | D9: Giá trị catalog chép trong sheet x=1
A10: Mô-men khởi động trực tiếp | B10: =Tinh_toan_x2!C43 -> 107.8 | C10: N·m | D10: Không coi là mô-men sẵn có khi chạy VFD
A11: Mô-men quỹ đạo có dự trữ | B11: =Tinh_toan_x2!E56 -> 42.049238 | C11: N·m | D11: Kiểm tra vận hành T_tăng=2 s
A12: Bao mô-men a_lim có dự trữ | B12: =Tinh_toan_x2!E57 -> 66.590513 | C12: N·m | D12: Yêu cầu quá tải ngắn hạn nếu khai thác a=0,5
A13: Mô-men RMS | B13: =Chu_ky!B26 -> 20.973821 | C13: N·m | D13: Chỉ số nhiệt sơ bộ; cần đường cong nhiệt hãng
A14: Tỷ số quá tải bao trên | B14: =Tinh_toan_x2!E59 -> 1.2354455 | D14: Cần đối chiếu VFD và thời gian quá tải
A15: Dòng motor | B15: =Tinh_toan_x2!C40 -> 12 | C15: A | D15: Theo sheet x=1
A16: Công suất VFD tối thiểu | B16: =1.3*Tinh_toan_x2!C33 -> 7.15 | C16: kW | D16: Theo yêu cầu ảnh
A17: Cấp VFD sơ bộ | B17: 7.5 | C17: kW | D17: Chọn tiếp theo; chưa chốt mã và dòng HD
A18: Dòng bảo vệ tối thiểu theo đề | B18: =1.5*Tinh_toan_x2!C40 -> 18 | C18: A | D18: Quy tắc bài tập; còn phối hợp bảo vệ VFD
A19: Cấp MCCB sơ bộ | B19: 20 | C19: A | D19: Chỉ theo ngưỡng 18 A; chưa chốt Icu, đặc tuyến
A20: Động năng có tải | B20: =0.5*(Tinh_toan_x2!E6+Tinh_toan_x2!E7+Tinh_toan_x2!E51)*Tinh_toan_x2!E9^2+0.5*(Tinh_toan_x2!C47+Tinh_toan_x2!E52+Tinh_toan_x2!E53/Tinh_toan_x2!E13^2)*Tinh_toan_x2!M35^2 -> 269.3088 | C20: J | D20: Giới hạn năng lượng cơ khi bỏ qua ma sát
A21: Năng lượng hãm có dự trữ | B21: =B20*Tinh_toan_x2!E16 -> 323.17056 | C21: J | D21: Không đủ để chốt điện trở Ω và W
A22: Điện trở hãm | B22: Cần catalog VFD | C22: Ω | D22: R ≥ Rmin, kiểm tra Udc, P_xung và chu kỳ
A23: Kiểm tra motor cho quỹ đạo | B23: =IF(AND(Tinh_toan_x2!C33*1000>=Chu_ky!B30,Tinh_toan_x2!C42>=Tinh_toan_x2!E56),"Đạt sơ bộ","CẦN CHỌN LẠI") -> Đạt sơ bộ | D23: Chưa xác nhận phát nhiệt thực tế
